Workbook

Sheet database
I1: =SUM(I4:I525) -> 103 | M1: =SUM(M4:M525) -> 86 | LL1: amino acids | LS1: anaesthetic | LZ1: analgesic | MH1: anti-acne preparation | MO1: antiarrhythmic agents | MV1: antiasthmatics | NC1: antibiotics | NJ1: anticoagulants/antithrombotics | NQ1: antidepressants | NX1: antidiabetics | OE1: antidiarrheals | OL1: antidiuretics | OS1: antidots | OZ1: antiepileptics | PG1: antifibrinolytics | PN1: antiglaucomatous | PU1: antihistamines | QB1: antihypertensives (Antihypertensive und Antihypertonikum) | QI1: antihypotonics | QP1: antimalarials | QW1: antimycotic | RD1: antiparkinsonian | RK1: antipsychotics | RR1: antiseptic agents | RY1: antithyroid | SF1: antitussive agents | SM1: antivertiginous | ST1: antivirals | TA1: beta-lactamase-inhibitor | TH1: bisphosphonates | TO1: butyrophenone | TV1: calcium channel blockers | UC1: cardiac glycoside | UJ1: contrast agent | UQ1: cytostatics | UX1: diuretics | VE1: mucokinetics (Exspektorans) | VL1: glucocorticoids | VS1: HIV medications | VZ1: hormones | WG1: hypnotics | WN1: immunomodulators | WU1: immunosuppressives | XB1: keratolytics | XI1: lipid-lowering agents | XP1: muscle relaxant | XW1: neuropathy agent | YD1: nootropics | YK1: other | YR1: parasympatholytics | YY1: parasympatomimetics | ZF1: phosphodiesterase inhibitors | ZM1: prokinetic agents | ZT1: prostaglandins | AAA1: prostate drug | AAH1: psychotropic drugs (benzodiazepine) | AAO1: spasmolytic | AAV1: sympatholytics | ABC1: sympathomimetics | ABJ1: ulcer therapeutic agents | ABQ1: uricostatics | ABX1: vein medication | ACE1: vaccination | ACL1: vasodilatator | ACS1: vasoconstrictor | ACZ1: blood | ADA1: card | ADB1: cong | ADC1: ear | ADD1: endo | ADE1: eye | ADF1: gastr | ADG1: genrl | ADH1: hepat | ADI1: immun | ADJ1: infec | ADK1: ing&P | ADL1: inv | ADM1: metab | ADN1: musc | ADO1: neopl | ADP1: nerv | ADQ1: preg | ADR1: psych | ADS1: renal | ADT1: repro | ADU1: resp | ADV1: skin | ADW1: socCi | ADX1: surg | ADY1: vasc | ADZ1: therapy | AEC1: laboratory
B2: =COUNTA(B4:B525) -> 162 | I2: stevens johnson syndrome | M2: toxic epidermal necrolysis | Q2: =SUM(Q4:Q525) -> 32 | R2: =SUM(R4:R525) -> 14 | S2: =SUM(S4:S525) -> 18 | T2: =SUM(T4:T525) -> 3 | U2: =SUM(U4:U525) -> 12 | V2: =SUM(V4:V525) -> 23 | W2: =SUM(W4:W525) -> 3 | X2: =SUM(X4:X525) -> 5 | ... LK2: =SUM(LK4:LK525) -> 0 | LL2: =COUNTA(LL4:LL525) -> 12 | LS2: =COUNTA(LS4:LS525) -> 24 | LZ2: =COUNTA(LZ4:LZ525) -> 420 | MH2: =COUNTA(MH4:MH525) -> 1 | MO2: =COUNTA(MO4:MO525) -> 5 | MV2: =COUNTA(MV4:MV525) -> 19 | NC2: =COUNTA(NC4:NC663) -> 126 | NJ2: =COUNTA(NJ4:NJ663) -> 44 | NQ2: =COUNTA(NQ4:NQ663) -> 18 | NX2: =COUNTA(NX4:NX663) -> 32 | OE2: =COUNTA(OE4:OE663) -> 5 | OL2: =COUNTA(OL4:OL663) -> 1 | OS2: =COUNTA(OS4:OS663) -> 10 | OZ2: =COUNTA(OZ4:OZ663) -> 43 | PG2: =COUNTA(PG4:PG663) -> 1 | PN2: =COUNTA(PN4:PN663) -> 1 | PU2: =COUNTA(PU4:PU663) -> 40 | QB2: =COUNTA(QB4:QB663) -> 72 | QI2: =COUNTA(QI4:QI663) -> 5 | QP2: =COUNTA(QP4:QP663) -> 1 | QW2: =COUNTA(QW4:QW663) -> 10 | RD2: =COUNTA(RD4:RD663) -> 3 | RK2: =COUNTA(RK4:RK663) -> 8 | RR2: =COUNTA(RR4:RR663) -> 2 | RY2: =COUNTA(RY4:RY663) -> 2 | SF2: =COUNTA(SF4:SF663) -> 1 | SM2: =COUNTA(SM4:SM663) -> 1 | ST2: =COUNTA(ST4:ST663) -> 9 | TA2: =COUNTA(TA4:TA663) -> 2 | TH2: =COUNTA(TH4:TH663) -> 4 | TO2: =COUNTA(TO4:TO663) -> 6 | TV2: =COUNTA(TV4:TV663) -> 8 | UC2: =COUNTA(UC4:UC663) -> 14 | UJ2: =COUNTA(UJ4:UJ663) -> 5 | UQ2: =COUNTA(UQ4:UQ663) -> 5 | UX2: =COUNTA(UX4:UX663) -> 83 | VE2: =COUNTA(VE4:VE663) -> 33 | VL2: =COUNTA(VL4:VL663) -> 65 | VS2: =COUNTA(VS4:VS524) -> 2 | VZ2: =COUNTA(VZ4:VZ663) -> 15 | WG2: =COUNTA(WG4:WG663) -> 8 | WN2: =COUNTA(WN4:WN663) -> 0 | WU2: =COUNTA(WU4:WU663) -> 7 | XB2: =COUNTA(XB4:XB663) -> 1 | XI2: =COUNTA(XI4:XI663) -> 8 | XP2: =COUNTA(XP4:XP663) -> 21 | XW2: =COUNTA(XW4:XW663) -> 3 | YD2: =COUNTA(YD4:YD663) -> 1 | YK2: =COUNTA(YK4:YK663) -> 232 | YR2: =COUNTA(YR4:YR663) -> 8 | YY2: =COUNTA(YY4:YY663) -> 5 | ZF2: =COUNTA(ZF4:ZF663) -> 2 | ZM2: =COUNTA(ZM4:ZM663) -> 23 | ZT2: =COUNTA(ZT4:ZT663) -> 5 | AAA2: =COUNTA(AAA4:AAA663) -> 0 | AAH2: =COUNTA(AAH4:AAH663) -> 57 | AAO2: =COUNTA(AAO4:AAO663) -> 1 | AAV2: =COUNTA(AAV4:AAV663) -> 5 | ABC2: =COUNTA(ABC4:ABC663) -> 17 | ABJ2: =COUNTA(ABJ4:ABJ663) -> 41 | ABQ2: =COUNTA(ABQ4:ABQ663) -> 40 | ABX2: =COUNTA(ABX4:ABX663) -> 1 | ACE2: =COUNTA(ACE4:ACE663) -> 0 | ACL2: =COUNTA(ACL4:ACL663) -> 32 | ACS2: =COUNTA(ACS4:ACS663) -> 2 | ADZ2: drug | AEA2: dosis | AEB2: duration | AEC2: date | AED2: AT III | AEE2: ALAT | AEF2: ASAT | AEG2: albumin | AEH2: CH50 | AEI2: CK (creatine phosphokinase) | AEJ2: creatinine | AEK2: CRP (c-reactive protein) | AEL2: D-dimers | AEM2: fibrinogen | AEN2: GOT | AEO2: GPT | AEP2: Hb | AEQ2: LDH | AER2: leucocytes/WBC | AES2: lymphocytes | AET2: blood myoglobin | AEU2: serum myoglobin | AEV2: neutrophils | AEW2: platelets | AEX2: prothrombin | AEY2: PTT | AEZ2: total protein | AFA2: troponin | AFB2: ANA | AFC2: Histone antibody | AFD2: direct immunofluorescence | AFE2: Anti-Ro antibody | AFF2: Anti-La antibody | AFG2: Anti dsDNA antibody
A3: Duplikate | B3: Bfarm | C3: Alter | D3: Geschlecht | E3: further information | F3: Death | G3: date | H3: reason | J3: onset | K3: duration | L3: TtO | N3: onset | O3: duration | P3: TtO | Q3: blister | R3: erythema | S3: pruritus/itching | T3: skin exfoliation | U3: rash/exanthema | V3: pyrexia/fever | W3: skin necrosis | X3: dermatitis bullous | Y3: conjunctivitis | Z3: hypersensitivty | AA3: stomatitis | AB3: pain | AC3: rash pustular | AD3: erythema multiforme | AE3: drug eruption | AF3: lip erosion | AG3: oedema | AH3: wound | AI3: pain of skin | AJ3: skin disorder | AK3: dermatitis | AL3: macule | AM3: mouth ulceration | AN3: mucosal erosion | AO3: nikolskys sign | AP3: skin burning sensation | AQ3: ALAT increased | AR3: dermatitis contact | AS3: skin reaction | AT3: blood lactate dehydrogenase increased | AU3: c reactive protein increased | AV3: dermatitis exfoliative | AW3: infection | AX3: leukocytosis | AY3: ocular hyperaemia | AZ3: oral mucosa erosion | BA3: sepsis | BB3: swelling | BC3: anaphylactic shock | BD3: ASAT increased | BE3: Gamma-glutamyltransferase increased | BF3: hypertension | BG3: leukopenia | BH3: rash macular | BI3: scab | BJ3: skin discoloration | BK3: skin ulceration | BL3: urticaria | BM3: actinic keratosis | BN3: angiodema | BO3: application site reaction | BP3: blood creatinin increased | BQ3: chills | BR3: condition aggravated | BS3: dermatitis allergic | BT3: dyspnoe | BU3: hepatic enyzme increased | BV3: inflammation | BW3: lip swelling | BX3: malaise | BY3: nausea | BZ3: secretion discharge | CA3: sleep disorder | CB3: vasculitis | CC3: acute generalised exanthematous pustulosis | CD3: acute kidney injury | CE3: dry skin/skin xerosis | CF3: eyelid oedema | CG3: injection site reaction | CH3: myalgia | CI3: skin erosion | CJ3: thermal burn | CK3: thrombocytopenia | CL3: wound secretion | CM3: application site erythema | CN3: asthenia | CO3: circulatory collapse | CP3: constipation | CQ3: cutaneous vasculitis | CR3: diarrhoea | CS3: flushing | CT3: genital erosion | CU3: haematoma | CV3: heart rate increased | CW3: herpes zoster | CX3: hypokalaemie | CY3: purpura | CZ3: rash vesicular | DA3: rhabdomyolysis | DB3: vomiting | DC3: abdominal discomfort | DD3: abscess | DE3: agranulocytosis | DF3: anxiety | DG3: arthralgia | DH3: arthritis | DI3: blood urea increased | DJ3: candida infection | DK3: cardiac failure | DL3: chest pain | DM3: cough | DN3: depressed level of consciousness | DO3: drug hypersensitivity | DP3: dysphagia/swallowing difficult | DQ3: eczema | DR3: fatigue | DS3: hepatotoxicity | DT3: hyperhidriosis | DU3: hyperuricaemia | DV3: impaired healing | DW3: lip ulceration | DX3: lymphadenopathie | DY3: lymphopenia | DZ3: medication error | EA3: mucosal inflammation | EB3: multi organ failure | EC3: necrosis | ED3: oedema peripheral | EE3: oral pain | EF3: oropharyngeal pain | EG3: overdose | EH3: papule | EI3: pharyngitis | EJ3: pulmonary congestion | EK3: rash erythematous | EL3: red blood cell sedimentation rate increased | EM3: scar | EN3: shock | EO3: skin lesion | EP3: swelling face | EQ3: swollen tongue | ER3: tubulointestitial nephritis | ES3: urinary tract infection | ET3: activated partial thromboplastin time prolonged | EU3: acute respiratory distress syndrom | EV3: agitation | EW3: anaemia | EX3: anal erosion | EY3: angina pectoris | EZ3: Bechterew's disease/ ankylosing spondylitis | FA3: anorectal disorder | FB3: application site discoloration | FC3: application site discharge | FD3: application site eczema | FE3: application site oedema | FF3: application site pruritus | FG3: arrhythmia supraventricular | FH3: asteatosis | FI3: atelectasis | FJ3: back pain | FK3: base excess increased | FL3: bleeding time prolonged | FM3: blood bicarbonate decreased | FN3: blood creatin phosphokinase increased | FO3: blood immunglobulin-E increased | FP3: blood magnesium abnormal | FQ3: borrelia infection | FR3: buccal muccosal roughening | FS3: burns first degree | FT3: burns second degree | FU3: capillaritis | FV3: chapped lips | FW3: cheilitis | FX3: chemical injury | FY3: chondritis | FZ3: coma hepatic | GA3: conduction disorder | GB3: confusional state | GC3: cystitis | GD3: cystitis haemorrhagic | GE3: dandruff | GF3: decreased appetite | GG3: dehydration | GH3: depression | GI3: disseminated intravascular coagulation | GJ3: dizziness | GK3: drug administration error | GL3: drug intolerance | GM3: dyspepsia | GN3: ear disorder | GO3: ear pain | GP3: ear swelling | GQ3: eczema asteatotic | GR3: eczema weeping | GS3: embolism arterial | GT3: enanthema | GU3: eosinophile count increased | GV3: epidermolysis | GW3: epidermolysis bullosa | GX3: ephelides/freckles | GY3: eye haemorrhage | GZ3: eye inflammation | HA3: face oedema | HB3: fascilitis | HC3: foot fraction | HD3: fuchs syndrome | HE3: gait disturbance | HF3: gastric ulcer haemorrhage | HG3: gastrointestinal erosion | HH3: gastrointestinal pain | HI3: glaucoma | HJ3: gout | HK3: granulocytopenia | HL3: haemorrhage | HM3: headache | HN3: heart rate decreased | HO3: hepatic neoplasm | HP3: hyperkeratosis | HQ3: hypersensitivity vasculitis | HR3: hypertensive crisis | HS3: hyperthyroidism | HT3: hyperventilation | HU3: hypoaesthesia | HV3: hypokinesia | HW3: increased tendecy to bruise | HX3: influenza | HY3: injection site inflammation | HZ3: jaundice | IA3: kreatitis | IB3: laceration | IC3: lip disorder | ID3: lipid metabolism disorder | IE3: lipoma | IF3: lipomatosis | IG3: lymphocyte count increased | IH3: melaena | II3: metabolic acidosis | IJ3: metaplasia | IK3: mouth swelling | IL3: mucosa vesicle | IM3: mucous membrane disorder | IN3: musculoskeletal stiffness | IO3: myositis | IP3: nasal disorder | IQ3: nasal inflammation | IR3: nasal mucosa disorder | IS3: nasal ulceration | IT3: nasopharyngitis | IU3: nodul | IV3: oral candidiasis | IW3: oral discorder | IX3: oral mucosal blistering | IY3: oral mucosal erythema | IZ3: overlap syndrome | JA3: oxygen saturation decreased | JB3: palpitations | JC3: palatal oedema | JD3: pancreatic enyzme increased | JE3: pancreatitis | JF3: pancytopenia | JG3: pancytopenia | JH3: paralysis | JI3: petechiae | JJ3: pigmentation disorder | JK3: pleural effusion | JL3: pneumonitis | JM3: poor peripheral circulation | JN3: PO2 decreased | JO3: proteinuria | JP3: prothrombin time prolonged | JQ3: pulmonary embolism | JR3: pulmonary oedema | JS3: purulent discharge | JT3: purpura fulminans | JU3: pyelonephritis | JV3: rash exfoliativ | JW3: rash maculo papular | JX3: rash papulosquamous | JY3: rash pruritic | JZ3: renal cyst | KA3: renal failure | KB3: renal vasculitis | KC3: respiratory failure | KD3: salivary hypersecretion | KE3: scotal pain | KF3: seizure | KG3: septic shock | KH3: sinus tachycardia | KI3: skin abrasion | KJ3: skin atrophie | KK3: skin haemorrhage | KL3: skin hyperpigmentation | KM3: skin hypertrophie | KN3: skin injury | KO3: skin neoplasm | KP3: skin oedema | KQ3: skin swelling | KR3: skin thightness | KS3: speech disorder | KT3: spinal osteoarthritis | KU3: streptococcus test postitive | KV3: tachycardia paroxysmal | KW3: throat irritation | KX3: thombosis | KY3: thyroid neoplasm | KZ3: tinitus | LA3: toxic shock syndrom | LB3: transient ischaemic attack | LC3: trychophytosis | LD3: vasodilatation | LE3: visual acuity reduced | LF3: weight increased | LG3: vulvovaginal rash | LH3: wound infection | LI3: xanthopsia | LJ3: yersinia infection | LK3: intraocular pressure increased | LL3: drug name | LM3: substance | LN3: dosis | LO3: duration | LP3: start date | LQ3: stop date | LR3: reason | LS3: drug name | LT3: substance | LU3: dosis | LV3: duration | LW3: start date | LX3: stop date | LY3: reason | LZ3: drug name | MA3: substance | MB3: dosis | MC3: duration | MD3: start date | ME3: stop date | MF3: route | MG3: reason | MH3: drug name | MI3: substance | MJ3: dosis | MK3: duration | ML3: start date | MM3: stop date | MN3: reason | MO3: drug name | MP3: substance | MQ3: dosis | MR3: duration | MS3: start date | MT3: stop date | MU3: reason | MV3: drug name | MW3: substance | MX3: dosis | MY3: duration | MZ3: start date | NA3: stop date | NB3: reason | NC3: drug name | ND3: substance | NE3: dosis | NF3: duration | NG3: start date | NH3: stop date | NI3: reason | NJ3: drug name | NK3: substance | NL3: dosis | NM3: duration | NN3: start date | NO3: stop date | NP3: reason | NQ3: drug name | NR3: substance | NS3: dosis | NT3: duration | NU3: start date | NV3: stop date | NW3: reason | NX3: drug name | NY3: substance | NZ3: dosis | OA3: duration | OB3: start date | OC3: stop date | OD3: reason | OE3: drug name | OF3: substance | OG3: dosis | OH3: duration | OI3: start date | OJ3: stop date | OK3: reason | OL3: drug name | OM3: substance | ON3: dosis | OO3: duration | OP3: start date | OQ3: stop date | OR3: reason | OS3: drug name | OT3: substance | OU3: dosis | OV3: duration | OW3: start date | OX3: stop date | OY3: reason | OZ3: drug name | PA3: substance | PB3: dosis | PC3: duration | PD3: start date | PE3: stop date | PF3: reason | PG3: drug name | PH3: substance | PI3: dosis | PJ3: duration | PK3: start date | PL3: stop date | PM3: reason | PN3: drug name | PO3: substance | PP3: dosis | PQ3: duration | PR3: start date | PS3: stop date | PT3: reason | PU3: drug name | PV3: substance | PW3: dosis | PX3: duration | PY3: start date | PZ3: stop date | QA3: reason | QB3: drug name | QC3: substance | QD3: dosis | QE3: duration | QF3: start date | QG3: stop date | QH3: reason | QI3: drug name | QJ3: substance | QK3: dosis | QL3: duration | QM3: start date | QN3: stop date | QO3: reason | QP3: drug name | QQ3: substance | QR3: dosis | QS3: duration | QT3: start date | QU3: stop date | QV3: reason | QW3: drug name | QX3: substance | QY3: dosis | QZ3: duration | RA3: start date | RB3: stop date | RC3: reason | RD3: drug name | RE3: substance | RF3: dosis | RG3: duration | RH3: start date | RI3: stop date | RJ3: reason | RK3: drug name | RL3: substance | RM3: dosis | RN3: duration | RO3: start date | RP3: stop date | RQ3: reason | RR3: drug name | RS3: substance | RT3: dosis | RU3: duration | RV3: start date | RW3: stop date | RX3: reason | RY3: drug name | RZ3: substance | SA3: dosis | SB3: duration | SC3: start date | SD3: stop date | SE3: reason | SF3: drug name | SG3: substance | SH3: dosis | SI3: duration | SJ3: start date | SK3: stop date | SL3: reason | SM3: drug name | SN3: substance | SO3: dosis | SP3: duration | SQ3: start date | SR3: stop date | SS3: reason | ST3: drug name | SU3: substance | SV3: dosis | SW3: duration | SX3: start date | SY3: stop date | SZ3: reason | TA3: drug name | TB3: substance | TC3: dosis | TD3: duration | TE3: start date | TF3: stop date | TG3: reason | TH3: drug name | TI3: substance | TJ3: dosis | TK3: duration | TL3: start date | TM3: stop date | TN3: reason | TO3: drug name | TP3: substance | TQ3: dosis | TR3: duration | TS3: start date | TT3: stop date | TU3: reason | TV3: drug name | TW3: substance | TX3: dosis | TY3: duration | TZ3: start date | UA3: stop date | UB3: reason | UC3: drug name | UD3: substance | UE3: dosis | UF3: duration | UG3: start date | UH3: stop date | UI3: reason | UJ3: drug name | UK3: substance | UL3: dosis | UM3: duration | UN3: start date | UO3: stop date | UP3: reason | UQ3: drug name | UR3: substance | US3: dosis | UT3: duration | UU3: start date | UV3: stop date | UW3: reason | UX3: drug name | UY3: substance | UZ3: dosis | VA3: duration | VB3: start date | VC3: stop date | VD3: reason | VE3: drug name | VF3: substance | VG3: dosis | VH3: duration | VI3: start date | VJ3: stop date | VK3: reason | VL3: drug name | VM3: substance | VN3: dosis | VO3: duration | VP3: start date | VQ3: stop date | VR3: reason | VS3: drug name | VT3: substance | VU3: dosis | VV3: duration | VW3: start date | VX3: stop date | VY3: reason | VZ3: drug name | WA3: substance | WB3: dosis | WC3: duration | WD3: start date | WE3: stop date | WF3: reason | WG3: drug name | WH3: substance | WI3: dosis | WJ3: duration | WK3: start date | WL3: stop date | WM3: reason | WN3: drug name | WO3: substance | WP3: dosis | WQ3: duration | WR3: start date | WS3: stop date | WT3: reason | WU3: drug name | WV3: substance | WW3: dosis | WX3: duration | WY3: start date | WZ3: stop date | XA3: reason | XB3: drug name | XC3: substance | XD3: dosis | XE3: duration | XF3: start date | XG3: stop date | XH3: reason | XI3: drug name | XJ3: substance | XK3: dosis | XL3: duration | XM3: start date | XN3: stop date | XO3: reason | XP3: drug name | XQ3: substance | XR3: dosis | XS3: duration | XT3: start date | XU3: stop date | XV3: reason | XW3: drug name | XX3: substance | XY3: dosis | XZ3: duration | YA3: start date | YB3: stop date | YC3: reason | YD3: drug name | YE3: substance | YF3: dosis | YG3: duration | YH3: start date | YI3: stop date | YJ3: reason | YK3: drug name | YL3: substance | YM3: dosis | YN3: duration | YO3: start date | YP3: stop date | YQ3: reason | YR3: drug name | YS3: substance | YT3: dosis | YU3: duration | YV3: start date | YW3: stop date | YX3: reason | YY3: drug name | YZ3: substance | ZA3: dosis | ZB3: duration | ZC3: start date | ZD3: stop date | ZE3: reason | ZF3: drug name | ZG3: substance | ZH3: dosis | ZI3: duration | ZJ3: start date | ZK3: stop date | ZL3: reason | ZM3: drug name | ZN3: substance | ZO3: dosis | ZP3: duration | ZQ3: start date | ZR3: stop date | ZS3: reason | ZT3: drug name | ZU3: substance | ZV3: dosis | ZW3: duration | ZX3: start date | ZY3: stop date | ZZ3: reason | AAA3: drug name | AAB3: substance | AAC3: dosis | AAD3: duration | AAE3: start date | AAF3: stop date | AAG3: reason | AAH3: drug name | AAI3: substance | AAJ3: dosis | AAK3: duration | AAL3: start date | AAM3: stop date | AAN3: reason | AAO3: drug name | AAP3: substance | AAQ3: dosis | AAR3: duration | AAS3: start date | AAT3: stop date | AAU3: reason | AAV3: drug name | AAW3: substance | AAX3: dosis | AAY3: duration | AAZ3: start date | ABA3: stop date | ABB3: reason | ABC3: drug name | ABD3: substance | ABE3: dosis | ABF3: duration | ABG3: start date | ABH3: stop date | ABI3: reason | ABJ3: drug name | ABK3: substance | ABL3: dosis | ABM3: duration | ABN3: start date | ABO3: stop date | ABP3: reason | ABQ3: drug name | ABR3: substance | ABS3: dosis | ABT3: duration | ABU3: start date | ABV3: stop date | ABW3: reason | ABX3: drug name | ABY3: substance | ABZ3: dosis | ACA3: duration | ACB3: start date | ACC3: stop date | ACD3: reason | ACE3: drug name | ACF3: substance | ACG3: dosis | ACH3: duration | ACI3: start date | ACJ3: stop date | ACK3: reason | ACL3: drug name | ACM3: substance | ACN3: dosis | ACO3: duration | ACP3: start date | ACQ3: stop date | ACR3: reason | ACS3: drug name | ACT3: substance | ACU3: dosis | ACV3: duration | ACW3: start date | ACX3: stop date | ACY3: reason
B4: 84000459 | C4: 39 | D4: f | F4: u | M4: 1 | LZ4: voltaren im | MA4: diclofenac sodium | MB4: 225mg | MC4: 3d | MD4: 30487 | ME4: 30490
LZ5: voltaren 50 | MA5: diclofenac sodium | MB5: 100mg/d | MC5: 14d | MD5: 30487 | ME5: 30500
B6: 84003222 | C6: 63 | D6: m | F6: u | M6: 1 | LZ6: voltaren im | MA6: diclofenac sodium | MB6: 75mg | MC6: 1d | MD6: 30876 | ME6: 30876
B7: 85002156 | C7: 78 | D7: m | F7: 1 | M7: 1 | LZ7: voltaren 50 | MA7: diclofenac sodium | MB7: 50mg/d | MC7: 3d | MD7: 31010 | ME7: 31012 | UC7: ianitop | UD7: metildigoxin | UE7: 1 Df/d | UF7: 14d | UG7: 31009 | UH7: 31023 | UX7: osyrol-lasix | UY7: spironolacton, furosemide | UZ7: 2Df/d | VA7: 6d | VB7: 31009 | VC7: 31014 | ABQ7: zyloric 300 | ABR7: allopurinol | ABS7: 300mg/d | ABT7: 3d | ABU7: 31010 | ABV7: 31012 | ACL7: isoket retard 20 | ACM7: isosorbide dinitrate | ACN7: 40mg/d | ACO7: 7d | ACP7: 31009 | ACQ7: 31015
B8: 86007764 | C8: 44 | D8: f | F8: u | I8: 1 | LZ8: diclofenac | MA8: diclofenac | MD8: 30847 | ME8: 30857 | NC8: phenoxymethylpenicillin | ND8: phenoxymethylpenicillin | NE8: 980mg/d | NF8: 5d | NG8: 30857 | NH8: 30861
LZ9: pacyl | MA9: isoxicam | MB9: 200mg/d | MC9: 11d | MD9: 30847 | ME9: 30857
LZ10: mofebutazon | MA10: mofebutazone | MB10: 500mg/d
LZ11: dipyron | MA11: metamizole sodium, theophylline nicotinate | MB11: 500mg/d | MC11: 2d | MD11: 30857 | ME11: 30858 | MG11: Analgetikum, Broncholytikum
B12: 87002161 | C12: 84 | D12: m | F12: u | I12: 1 | LZ12: alrheumun | MA12: ketoprofen
LZ13: imbun | MA13: ibuprofen lysinate
LZ14: diclo-phlogont | MA14: diclofenac sodium
LZ15: voltaren | MA15: diclofenac sodium
B16: 88010068 | C16: 36 | D16: m | F16: 1 | M16: 1 | W16: 1 | BA16: 1 | LZ16: diclofenac | MA16: diclofenac | MB16: 75mg | MD16: 32264 | VL16: dexa-phlogont | VM16: cyanocobalamin, predisolone, dexamethasone, lidocaine hydrochloride | VN16: 1Df | VP16: 32264 | VR16: Vitamine, Lokalanästhetikum, Glukocorticoid
B17: 88017092 | C17: 57 | D17: m | F17: 1 | M17: 1 | T17: 1 | LZ17: voltaren | MA17: diclofenac sodium | MB17: 50mg/d | MC17: 5d | MD17: 32409 | ME17: 32413 | NC17: amoxicillin | ND17: amoxicillin | NE17: 3000mg/d | NF17: 6d | NG17: 32409 | NH17: 32414
B18: 89007042 | C18: 51 | D18: f | F18: 1 | M18: 1 | LZ18: diclo-phlogont | MA18: diclofenac sodium | MB18: /d | MC18: 5d | MD18: 32616 | ME18: 32620
LZ19: treupel | MA19: phenactin, acetylsalicylic acid, codeine phosphate | MC19: 5d | MD19: 32616 | ME19: 32620
B20: 90000259 | C20: 64 | D20: m | F20: 1 | M20: 1 | V20: 1 | X20: 1 | BQ20: 1 | CY20: 1 | FG20: 1 | HQ20: 1 | LZ20: boxazin | MA20: acetylsalicylic acid, ascorbic acid | MB20: 1Df/d | MC20: 2d | MD20: 32807 | ME20: 32808
LZ21: diclofenac ratiopharm | MA21: diclofenac sodium | MB21: 175mg/d | MC21: 2d | MD21: 32807 | ME21: 32808
B22: 90013820 | C22: 78 | D22: f | F22: u | M22: 1 | LZ22: voltaren emulgel | MA22: diclofenac diethylamine | MB22: /d | MD22: 32690
B23: 91900065 | C23: 90 | D23: f | F23: 1 | M23: 1 | LZ23: voltaren retard | MA23: diclofenac sodium | MB23: 1Df/d | MC23: 27d | MD23: 33147 | ME23: 33173 | NC23: spizef | ND23: cefotiam hydrochloride | NE23: 6000mg/d | NF23: 10d | NG23: 33151 | NH23: 33160 | NJ23: heparin | NK23: heparin | NL23: 15kiu/d | NM23: 28d | NN23: 33147 | NO23: 33173 | NQ23: ludiomil | NR23: maprotiline hydrochloride | NS23: 50mg/d | NT23: 4d | NU23: 33170 | NV23: 33173 | QI23: effortil | QJ23: etilefrine hydrochloride | QK23: 2Df/ | QM23: 33151 | UC23: novodigal | UD23: beta-acetyldigoxin | UE23: 1Df/d | UF23: 28d | UG23: 33147 | UH23: 33173 | YK23: aristochol | YL23: absinthium, taraxacum officinale, flores stoechados, chelidonine, frangula, fructus cardui mariae, tumeric, achillea | YM23: 1Df/D | YN23: 10d | YO23: 33164 | YP23: 33173 | YQ23: Gallekapseln | YY23: ubretid | YZ23: distigmine bromide | ZA23: 1Df/d | ZB23: 13d | ZC23: 33161 | ZD23: 33173 | AAO23: cholspasmin forte | AAP23: hymecromone | AAQ23: 3Df/d | AAR23: 10d | AAS23: 33164 | AAT23: 33173
B24: 91002263 | C24: 72 | D24: m | F24: 0 | M24: 1 | X24: 1 | LZ24: diclofenac 50 stada | MA24: diclofenac sodium | MB24: 75mg/d | MC24: 32d | MD24: 33337 | ME24: 33368
B25: 91010586 | C25: 82 | D25: f | F25: 0 | I25: 1 | J25: 33004 | LZ25: diclofenac | MA25: diclofenac | MB25: 5Df/d | MC25: 10d | MD25: 32995 | ME25: 33004 | UX25: luret | UY25: azosemide | UZ25: 1Df/d | VA25: 42d | VB25: 32964 | VC25: 33035 | YK25: liquifilm | YL25: polyvinyl alcohol | YM25: 3Df/d | YN25: 3d | YO25: 33002 | YP25: 33004 | YQ25: künstliche Tränen
LZ26: togal | MA26: acetylsalicylic acid, quinin citrate, lithium citrate | MG26: Muskelrelaxans (Chinin citrat), Antipsychotika (Lithium)
LZ27: valoron n | MA27: naloxone hydrochloride, tilidine hydrochloride | MB27: /a | MC27: 42s | MD27: 32964 | ME27: 33004 | MG27: Antidot, Opioid-Analgetikum Kombi
B28: 91010587 | C28: 79 | D28: m | F28: 0 | I28: 1 | J28: 33002 | LZ28: diclofenac | MA28: diclofenac | MB28: 2Df/d | MC28: 2d | MD28: 33001 | ME28: 33002 | NC28: eusaprim | ND28: trimethoprim, sulfamethoxazole | NE28: 2Df/d | NF28: 2d | NG28: 33001 | NH28: 33002 | TV28: veratide | TW28: verapamil hydrochloride | TX28: 1Df/d | UA28: 33003 | UC28: novodigal | UD28: beta-acetyldigoxin | UE28: 1Df/d | UH28: 33003 | YK28: azuprostat | YL28: tocopheryl acetat, retinol palmitate, sitosterol, echinacea purpurea | YM28: 3Df/d | YP28: 33003 | YQ28: Vitamine und Immun | ACL28: corangin 60 retard | ACM28: isosorbide mononitrate | ACN28: 1Df/d | ACQ28: 33003
B29: 91010598 | C29: 42 | D29: m | F29: 0 | I29: 1 | J29: 33191 | LZ29: voltaren | MA29: diclofenac sodium | ME29: 33189 | MV29: theophyllin | MW29: theophyllin | NA29: 33189 | PU29: sostril | PV29: ranitidine hydrochloride | PZ29: 33189 | TO29: haldol | TP29: haloperidol | TQ29: 60Df/d | TT29: 33197 | UC29: novodigal | UD29: beta-acetyldigoxin | UE29: 1Df/d | UH29: 33197 | UX29: spiro comb. Forte-ratiopharm | UY29: spironolactone, furosemide | UZ29: 2Df/d | VC29: 33197 | VL29: sanasthmax | VM29: beclometasone dipropionate | VN29: 8Df/d | VO29: 8d | VP29: 33190 | VQ29: 33197 | YR29: ipratropium bromide | YS29: ipratropium bromide | YW29: 33189 | AAH29: diazepam | AAI29: diazepam | AAJ29: 10mg/ | AAM29: 33189 | ABQ29: zyloric 300 | ABR29: allopurinol | ABS29: 1Df/d | ABV29: 33189
LZ30: mst | MA30: morphin sulfate | MB30: 3Df/d | ME30: 33197 | MG30: Opioid | MV30: aerodur | MW30: terbutaline sulfate | MX30: 8Df/d | MY30: 8d | MZ30: 33190 | NA30: 33197 | PU30: zantic | PV30: ranitidine hydrochloride | PX30: 4d | PY30: 33190 | PZ30: 33193 | VL30: sanasthmyl | VM30: beclometasone dipropionate | VN30: 8Df/d | VQ30: 33189
MV31: salbutamol | MW31: salbutamol | NA31: 33189 | VL31: solu-decortin-h | VM31: prednisolon sodium succinate | VN31: 25mg/d | VQ31: 33193
MV32: bronchoparat | MW32: theophyllin sodium aminoacetate | MX32: 2Df/d | MY32: 4d | MZ32: 33190 | NA32: 33193
B33: 92900215 | C33: 80 | D33: m | F33: 0 | I33: 1 | J33: 33528 | M33: 1 | N33: 33528 | LL33: acimethin | LM33: methionine, active | LN33: 2Df/d | LO33: 25d | LP33: 33503 | LQ33: 33528 | LZ33: allvoran | MA33: diclofenac sodium | MB33: 1Df/d | MC33: 25d | MD33: 33503 | ME33: 33523 | NC33: supracombin | ND33: streptomycin panthothenate, clemizole penicillin, streptomycin sulfate | NF33: 2d | NG33: 33528 | NH33: 33529 | NI33: urinary tract infection | NQ33: ludiomil | NR33: maprotiline hydrochloride | NS33: 1Df/d | NT33: 25d | NU33: 33503 | NV33: 33528 | QB33: nifelat retard | QC33: nifedipine | QD33: 2Df/d | QE33: 25d | QF33: 33503 | QG33: 33528 | QH33: Antihypertonikum | UX33: tensoflux | UY33: bendroflumethiazide, amiloride hydrochloride | UZ33: 1Df/d | VA33: 25d | VB33: 33503 | VC33: 33528 | XP33: lioresal | XQ33: baclofen | XR33: 3Df/d | XS33: 25d | XT33: 33503 | XU33: 33528 | AAH33: rohypnol | AAI33: flunitrazepam | AAJ33: 0,5Df/d | AAK33: 25d | AAL33: 33503 | AAM33: 33523 | ADF33: paralytic ileus | ADP33: quadriplegia
B34: 92900471 | C34: 39 | D34: m | F34: u | M34: 1 | N34: 33767 | O34: 14d | EK34: 1 | LZ34: diclefenac ratiopharm sf | MA34: diclofenac sodium | MB34: 75mg/d | MC34: 2d | MD34: 33764 | ME34: 33765 | MF34: intravenous | MG34: lumbago | ADP34: sciatica
B35: 92008030 | C35: 66 | D35: f | F35: u | I35: 1 | J35: 33414 | LZ35: diclofenac 100 retard | MA35: diclofenac sodium | MB35: 100mg/d | MC35: 6d | MD35: 33410 | ME35: 33415 | VZ35: l-thyroxin | WA35: levothyroxine sodium | WB35: 0,1mg/d | WC35: 19d | WD35: 33399 | WE35: 33417 | ZM35: gastrosil | ZN35: metoclopramide hydrochloride | ZO35: 20mg/d | ZP35: 5d | ZQ35: 33406 | ZR35: 33410 | ZT35: cytotec | ZU35: misoprostol | ZV35: 400mg/d | ZW35: 19d | ZX35: 33399 | ZY35: 33417 | ACL35: ismo 20 | ACM35: isosorbide mononitrate | ACN35: 40mg/d | ACO35: 19d | ACP35: 33399 | ACQ35: 33417
LZ36: tauredon 20 | MA36: sodium aurothiomalate | MB36: 20mg/d | MC36: 1d | MD36: 33406 | ME36: 33406 | MG36: Antirheumatikum (Goldverbindung) viele UAWs
LZ37: fluniget | MA37: diflunial | MB37: 2Df/d | MC37: 18d | MD37: 33399 | ME37: 33416 | MG37: NSAID
B38: 92008032 | C38: 78 | D38: f | F38: 0 | I38: 1 | J38: 33487 | LZ38: diclofenac 50 | MA38: diclofenac sodium | MB38: 100mg/d | MC38: 34d | MD38: 33453 | ME38: 33487 | NC38: megacillin oral | ND38: phenoxymethylpenicillin potassium | NF38: 3d | NG38: 33485 | NH38: 33487 | PU38: vertigo-vomex | PV38: pyridoxine hydrochloride, nicotinic acid, dimenhydrinate | PZ38: 33487 | QA38: Vitamin, Cholesterinsenker, Antihistaminika Kombi | QB38: dihydralazine | QC38: dihydralazine | QD38: 1Df/d | QG38: 33487 | RD38: hydergin forte | RE38: dihydroergocryptine mesilate, dihydroergocorine mesilate, dihydroergocristine mesilate | RI38: 33491 | UC38: digimerck 0,1 tab | UD38: digitoxin | UE38: 1Df/d | UF38: 5d | UG38: 33487 | UH38: 33491 | UX38: tensobon comp | UY38: hydrochlorothiazide, captopril | VC38: 33487 | VD38: Diuretika, Antihypertonika Kombi | VL38: solu-decortin-h | VM38: prednisolon sodium succinate | VN38: 250mg/d | VO38: 5d | VP38: 33487 | VQ38: 33491 | YK38: lefax | YL38: dimeticone, silicon dioxide, colloidal | YP38: 33487 | ZM38: gastrosil | ZN38: metoclopramide hydrochloride | ZR38: 33487 | AAH38: lexotanil | AAI38: bromazepam | AAJ38: 1Df/d | AAM38: 33487 | ACL38: ismo 20 | ACM38: isosorbide mononitrate | ACN38: 40mg/d | ACQ38: 33491 | ADA38: several (atrial fibrillation and flutter, angina pectoris, ischaemic heart disease, ischaemic cerebrovascular disease | ADR38: unspecific organic brain syndrom | ADY38: essential hypertension, unspecified
PU39: fensitil | PV39: dimetindene maleate | PX39: 5d | PY39: 33487 | PZ39: 33491 | YK39: kalium-duriles | YL39: potassium chloride | YM39: 1Df/d | YN39: 5d | YO39: 33487 | YP39: 33491 | AAH39: tranxilium | AAI39: clorazepate dipotassium | AAJ39: 1Df/d | AAM39: 33487 | ACL39: circo-maren | ACM39: nicergoline | ACN39: 2Df/d | ACQ39: 33487 | ACR39: Nootropikum fürs Gehirn
B40: 92900655 | C40: 24 | D40: f | F40: 0 | I40: 1 | J40: 33272 | BU40: 1 | HZ40: 1 | LS40: lidocaine | LT40: lidocaine | LU40: 1Df | LV40: 1d | LW40: 33257 | LX40: 33257 | LY40: LA | LZ40: aspirin | MA40: acetylsalicylic acid | MB40: 2Df/d | MC40: 28d | MD40: 33241 | ME40: 33270 | NC40: augmentan | ND40: amoxicillin trihydrate, clavulanic acid | NF40: 1d | NG40: 33240 | NH40: 33240 | OZ40: resimatil | PA40: primidone | PB40: 3Df/d | QW40: ampho-moronal | QX40: amphotericin b | QY40: 2Df | QZ40: 1d | RA40: 33258 | RB40: 33258 | VL40: volon a haftsalbe | VM40: triamcinolone acetonide | XB40: carbamid | XC40: urea | XP40: muskel trancopal | XQ40: chlormezanone | XR40: 1Df | XS40: 1d | XT40: 33257 | XU40: 33257 | YK40: Sinupret | YL40: primula flowers, ascorbic acid, sambucus flowers, gentiana, verbena herb, rumicis asetosa | YM40: 6Df/d | YO40: 33239 | ADJ40: influenza
...

Sheet interim analysis
A1: interim analysis
A3: gender | I3: outcome | Q3: average age | R3: =database!C526 -> 58.101911 | AB3: medication
A4: female | B4: =database!E526 -> 89 | I4: dead | J4: =database!G526 -> 46 | AB4: a-z | AE4: 100-0
A5: male | B5: =database!E527 -> 68 | I5: recovered | J5: =database!G527 -> 54 | AB5: amino acids | AC5: 12 | AE5: analgesic | AF5: 664
A6: unknown | B6: =database!E528 -> 5 | I6: unnknown | J6: =database!G528 -> 62 | AB6: anaesthetic | AC6: 28 | AE6: other | AF6: 244
A7: total | B7: =SUM(B4:B6) -> 162 | I7: total | J7: =SUM(J4:J6) -> 162 | AB7: analgesic | AC7: 664 | AE7: antibiotics | AF7: 133
AB8: anti-acne preparation | AC8: 1 | AE8: diuretics | AF8: 94
AB9: antiarrhythmic agents | AC9: 6 | AE9: antihypertensives | AF9: 90
AB10: antiasthmatics | AC10: 22 | AE10: glucocorticoids | AF10: 77
AB11: antibiotics | AC11: 133 | AE11: psychotropic drugs | AF11: 57
AB12: anticoagulants/antithombotics | AC12: 52 | AE12: anticoagulants/antithombotics | AF12: 52
AB13: antidepressants | AC13: 22 | AE13: ulcer therapeutic agents | AF13: 47
A14: 103 | B14: SJS | O14: analgesic | P14: 420 | AB14: antidiabetics | AC14: 42 | AE14: antihistamines | AF14: 45
A15: 86 | B15: TEN | O15: other | P15: 232 | AB15: antidiarrheals | AC15: 4 | AE15: uricostatics | AF15: 44
A16: 32 | B16: blister | O16: antibiotics | P16: 126 | AB16: antidiuretics | AC16: 2 | AE16: antiepileptics | AF16: 43
A17: 23 | B17: pyrexia/fever | O17: diuretics | P17: 83 | AB17: antidits | AC17: 13 | AE17: antidiabetics | AF17: 42
A18: 18 | B18: pruritus/itching | O18: antihypertensives (Antihypertensive und Antihypertonikum) | P18: 72 | AB18: antiepileptics | AC18: 43 | AE18: mucokinetics | AF18: 33
A19: 15 | B19: conjunctivitis | O19: glucocorticoids | P19: 65 | AB19: antifibrinolytics | AC19: 1 | AE19: vasodilatator | AF19: 32
A20: 14 | B20: erythema | O20: psychotropic drugs (benzodiazepine) | P20: 57 | AB20: antiglaucomatous | AC20: 6 | AE20: anaesthetic | AF20: 28
A21: 13 | B21: lip erosion | O21: anticoagulants/antithrombotics | P21: 44 | AB21: antihistamines | AC21: 45 | AE21: prokinetic agents | AF21: 25
A22: 13 | B22: nikolskys sign | O22: antiepileptics | P22: 43 | AB22: antihypertensives | AC22: 90 | AE22: muscle relaxant | AF22: 24
A23: 12 | B23: rash/exanthema | O23: ulcer therapeutic agents | P23: 41 | AB23: antihypotonics | AC23: 5 | AE23: antiasthmatics | AF23: 22
A24: 12 | B24: mucosal erosion | O24: antihistamines | P24: 40 | AB24: antimalarials | AC24: 2 | AE24: antidepressants | AF24: 22
A25: 9 | B25: pain of skin | O25: uricostatics | P25: 40 | AB25: antimycotic | AC25: 9 | AE25: cardiac glycoside | AF25: 16
... A69: 2 | B69: cough | O69: antimalarials | P69: 1 | AB69: vasoconstrictor | AC69: 2 | AE69: vaccination | AF69: 1
A70: 2 | B70: fatigue | O70: antitussive agents | P70: 1
A71: 2 | B71: hyperuricaemia | O71: antivertiginous | P71: 1
A72: 2 | B72: lip ulceration | O72: keratolytics | P72: 1
A73: 2 | B73: lymphopenia | O73: nootropics | P73: 1
A74: 2 | B74: mucosal inflammation | O74: spasmolytic | P74: 1
A75: 2 | B75: multi organ failure | O75: vein medication | P75: 1
A76: 2 | B76: shock | O76: immunomodulators | P76: 0
A77: 2 | B77: urinary tract infection | O77: prostate drug | P77: 0
A78: 2 | B78: blood creatin phosphokinase increased | O78: vaccination | P78: 0
A79: 2 | B79: cheilitis
A80: 1 | B80: skin reaction
A81: 1 | B81: skin ulceration
A82: 1 | B82: urticaria
A83: 1 | B83: angiodema
A84: 1 | B84: malaise
...

Sheet Tabelle1
E1: analgesic | F1: 420
E2: other | F2: 232
E3: antibiotics | F3: 126
E4: diuretics | F4: 83
E5: antihypertensives (Antihypertensive und Antihypertonikum) | F5: 72
E6: glucocorticoids | F6: 65
E7: psychotropic drugs (benzodiazepine) | F7: 57
E8: anticoagulants/antithrombotics | F8: 44
E9: antiepileptics | F9: 43
E10: ulcer therapeutic agents | F10: 41
E11: antihistamines | F11: 40
E12: uricostatics | F12: 40
... E65: vaccination | F65: 0
