Workbook
Name Farbe: ZELLE:ZUORDNEN(63,INDIRECT("ZS(-1)",))

Sheet Column header
A1: BfArM Nummer | B1: Edited_BfArM Nummer2 | C1: Edited_BfArM Nummer3 with Function
A2: Diagnose | B2: Diagnose | C2: =PROPER('Column header'!$B2) -> Diagnose
A3: CK-12 Tage vor Krankheitsbeginn | B3: CK Day 12_From Start | C3: =PROPER('Column header'!$B3) -> Ck Day 12_From Start
A4: CK-11 Tage vor Krankheitsbeginn | B4: CK Day 11_From Start | C4: =PROPER('Column header'!$B4) -> Ck Day 11_From Start
A5: CK-7 Tage vor Krankheitsbeginn | B5: CK Day 7_From Start | C5: =PROPER('Column header'!$B5) -> Ck Day 7_From Start
A6: CK-6 Tage vor Krankheitsbeginn | B6: CK Day 6_From Start | C6: =PROPER('Column header'!$B6) -> Ck Day 6_From Start
A7: CK-4 Tage vor Krankheitsbeginn (U\l) | B7: CK Day 4_From Start | C7: =PROPER('Column header'!$B7) -> Ck Day 4_From Start
A8: CK-3 Tage vor Krankheitsbeginn | B8: CK Day 3_From Start | C8: =PROPER('Column header'!$B8) -> Ck Day 3_From Start
A9: CK-2 Tage vor Krankheitsbeginn (U\l) | B9: CK Day 2_From Start | C9: =PROPER('Column header'!$B9) -> Ck Day 2_From Start
A10: CK-1 Tag vor Krankheitsbeginn (U\l) | B10: CK Day 1_From Start | C10: =PROPER('Column header'!$B10) -> Ck Day 1_From Start
A11: CK-Datum unbekannt | B11: CK Day_Unknown | C11: =PROPER('Column header'!$B11) -> Ck Day_Unknown
A12: CK-d1 (U\l) | B12: Ck Day1 | C12: =PROPER('Column header'!$B12) -> Ck Day1
A13: Ck-d2 | B13: Ck Day2 | C13: =PROPER('Column header'!$B13) -> Ck Day2
... A1509: MCHC- (g/dl) d4w3m2 | B1509: MCHC Day81 | C1509: =PROPER('Column header'!$B1509) -> Mchc Day81
A1510: Reticulozyten-11 Tage vor Krankheisbeginn | C1510: =PROPER('Column header'!$B1510)
A1511: Reticulozyten-Datum unbekannt (% pro 1000 Erys) | C1511: =PROPER('Column header'!$B1511)
A1512: Reticulozyten-d2(% pro 1000 Erys) | C1512: =PROPER('Column header'!$B1512)
A1513: Reticulozyten-d3 | C1513: =PROPER('Column header'!$B1513)
A1514: Anti-HAV-IgG (0=negativ, 1=positiv) | C1514: =PROPER('Column header'!$B1514)
A1515: EBV-VCA-IgG (0=negativ, 1=positiv) | C1515: =PROPER('Column header'!$B1515)
A1516: Epstein-Barr-IgM-d7 (0=negativ, 1=positiv) | C1516: =PROPER('Column header'!$B1516)
A1517: Cytomegalievirus (0=negativ, 1=positiv) | C1517: =PROPER('Column header'!$B1517)
A1518: ANA(Antinukleäre Antikörper)-Datum umbekannt (0=negativ, 1=positiv) | C1518: =PROPER('Column header'!$B1518)
A1519: Anti-Ro (SSA(Ro)-Antikörper)-Datum unbekannt (0=negativ, 1=positiv) | C1519: =PROPER('Column header'!$B1519)
A1520: Anti-La (SSB(La)-Antikörper)-Datum unbekannt (0=negativ, 1=positiv) | C1520: =PROPER('Column header'!$B1520)
A1521: Antihistonantikörper-Datum unbekannt (0=negativ, 1=positiv) | C1521: =PROPER('Column header'!$B1521)
... A1537: HLA B51 (0=negativ, 1=positiv) | C1537: =PROPER('Column header'!$B1537)
A1538: Natrium-11 Tage vor Krankheitsbeginn (mmol/l) | B1538: Natrium Day11_From Start | C1538: =PROPER('Column header'!$B1538) -> Natrium Day11_From Start
A1539: Natrium-9 Tage vor Krankheitsbeginn (mmol/l) | B1539: Natrium Day9_From Start | C1539: =PROPER('Column header'!$B1539) -> Natrium Day9_From Start
A1540: Natrium-8 Tage vor Krankheitsbeginn | B1540: Natrium Day8_From Start | C1540: =PROPER('Column header'!$B1540) -> Natrium Day8_From Start
A1541: Natrium-7 Tage vor Krankheitsbeginn | B1541: Natrium Day7_From Start | C1541: =PROPER('Column header'!$B1541) -> Natrium Day7_From Start
A1542: Natrium-5 Tage vor Krankheitsbeginn | B1542: Natrium Day5_From Start | C1542: =PROPER('Column header'!$B1542) -> Natrium Day5_From Start
A1543: Natrium-3 Tage vor Krankheitsbeginn | B1543: Natrium Day3_From Start | C1543: =PROPER('Column header'!$B1543) -> Natrium Day3_From Start
A1544: Natrium-2 Tage vor Krankheitsbeginn | B1544: Natrium Day2_From Start | C1544: =PROPER('Column header'!$B1544) -> Natrium Day2_From Start
A1545: Natrium-1 Tage vor Krankheitsbeginn | B1545: Natrium Day1_From Start | C1545: =PROPER('Column header'!$B1545) -> Natrium Day1_From Start
A1546: Natrium-Datum unbekannt | B1546: Natrium Day_Unknown | C1546: =PROPER('Column header'!$B1546) -> Natrium Day_Unknown
A1547: Natrium (Sodium)-d1 (mmol/l) | B1547: Natrium Day1 | C1547: =PROPER('Column header'!$B1547) -> Natrium Day1
A1548: Natrium-d2 | B1548: Natrium Day2 | C1548: =PROPER('Column header'!$B1548) -> Natrium Day2
A1549: Natrium-d3 | B1549: Natrium Day3 | C1549: =PROPER('Column header'!$B1549) -> Natrium Day3
... A1722: Lactat-8 Tage vor Krankheitsbeginn (mmol/l) | B1722: Lactat Day8_From Start | C1722: =PROPER('Column header'!$B1722) -> Lactat Day8_From Start
...

Sheet Sheet3
A1: Edited_BfArM Nummer2 | B1: Diagnose | C1: CK Day 12_From Start | D1: CK Day 11_From Start | E1: CK Day 7_From Start | F1: CK Day 6_From Start | G1: CK Day 4_From Start | H1: CK Day 3_From Start | I1: CK Day 2_From Start | J1: CK Day 1_From Start | K1: CK Day_Unknown | L1: Ck Day1 | M1: Ck Day2 | N1: Ck Day3 | O1: Ck Day4 | P1: Ck Day5 | Q1: Ck Day6 | R1: Ck Day7 | S1: Ck Day8 | T1: Ck Day9 | U1: Ck Day10 | V1: Ck Day11 | W1: Ck Day12 | X1: Ck Day13 | Y1: Ck Day14 | Z1: Ck Day15 | AA1: Ck Day16 | AB1: Ck Day17 | AC1: CK-MB Day4_From Start | AD1: CK-MB Day4_From Start | AE1: CK-MB Day4_From Start | AF1: CK-MB Day1 | AG1: CK-MB Day2 | AH1: CK-MB Day3 | AI1: CK-MB Day4 | AJ1: CK-MB Day5 | AK1: CK-MB Day6 | AL1: CK-MB Day7 | AM1: CK-MB Day9 | AN1: CK-MB Day10 | AO1: CK-MB Day11 | AP1: CK-MB Day13 | AQ1: CK-MB Day18 | AR1: CK-MB Day24 | AS1: CK-MB Day15 | AT1: Quick Day37_From Start | AU1: Quick Day12_From Start | AV1: Quick Day11_From Start | AW1: Quick Day8_From Start | AX1: Quick Day7_From Start | AY1: Quick Day3_From Start | AZ1: Quick Day2_From Start | BA1: Quick Day_From Start | BB1: Quick Day_Unknown | BC1: Quick Day1 | BD1: Quick Day2 | BE1: Quick Day3 | BF1: Quick Day4 | BG1: Quick Day5 | BH1: Quick Day6 | BI1: Quick Day7 | BJ1: Quick Day8 | BK1: Quick Day9 | BL1: Quick Day10 | BM1: Quick Day11 | BN1: Quick Day12 | BO1: Quick Day13 | BP1: Quick Day15 | BQ1: Quick Day16 | BR1: Quick Day17 | BS1: Quick Day20 | BT1: Quick Day22 | BU1: Quick Day23 | BV1: Quick Day24 | BW1: Quick Day34 | BX1: Quick Day35 | BY1: Quick Day49 | BZ1: Quick Day55 | CA1: Quick Day70 | CB1: Quick Day79 | CC1: Quick Day92 | CD1: Quick Day103 | CE1: INR Day12_From Start | CF1: INR Day11_From Start | CG1: INR Day8_From Start | CH1: INR Day7_From Start | CI1: INR Day3_From Start | CJ1: INR Day2_From Start | CK1: INR Day1_From Start | CL1: INR Day_Unknown | CM1: INR Day1 | CN1: INR Day2 | CO1: INR Day3 | CP1: INR Day4 | CQ1: INR Day5 | CR1: INR Day6 | CS1: INR Day7 | CT1: INR Day8 | CU1: INR Day9 | CV1: INR Day10 | CW1: INR Day11 | CX1: INR Day13 | CY1: INR Day16 | CZ1: INR Day22 | DA1: INR Day23 | DB1: INR Day35 | DC1: INR Day36 | DD1: INR Day49 | DE1: INR Day55 | DF1: INR Day79 | DG1: INR Day92 | DH1: INR Day103 | DI1: Troponin I Day2_From Start | DJ1: Troponin I Day1_From Start | DK1: Troponin I Day_Unknown | DL1: Troponin I Day51 | DM1: Troponin I Day56 | DN1: Prothrombin Day14_From Start | DO1: Prothrombin Day6_From Start | DP1: Prothrombin Day3_From Start | DQ1: Prothrombin Day2_From Start | DR1: Prothrombin Day1_From Start | DS1: Prothrombin Day_Unknown | DT1: Prothrombin Day1 | DU1: Prothrombin Day2 | DV1: Prothrombin Day5 | DW1: PTT Day1100_From Start (~3Y) | DX1: PTT Day12_From Start | DY1: PTT Day11_From Start | DZ1: PTT Day8_From Start | EA1: PTT Day7_From Start | EB1: PTT Day6_From Start | EC1: PTT Day5_From Start | ED1: PTT Day4_From Start | EE1: PTT Day2_From Start | EF1: PTT Day_Unknown | EG1: PTT Day1 | EH1: PTT Day2 | EI1: PTT Day3 | EJ1: PTT Day4 | EK1: PTT Day5 | EL1: PTT Day6 | EM1: PTT Day7 | EN1: PTT Day8 | EO1: PTT Day9 | EP1: PTT Day10 | EQ1: PTT Day11 | ER1: PTT Day12 | ES1: PTT Day15 | ET1: PTT Day16 | EU1: PTT Day17 | EV1: PTT Day22 | EW1: PTT Day23 | EX1: PTT Day34 | EY1: PTT Day35 | EZ1: PTT Day49 | FA1: PTT Day55 | FB1: PTT Day79 | FC1: PTT Day103 | FD1: TZ Day1_From Start | FE1: TZ Day1 | FF1: TZ Day2 | FG1: TZ Day3 | FH1: TZ Day4 | FI1: TZ Day7 | FJ1: TZ Day9 | FK1: TZ Day10 | FL1: TZ Day11 | FM1: Antithrombin 3 (AT-III) Day_Unknown | FN1: Antithrombin 3 (AT-III) Day1 | FO1: Antithrombin 3 (AT-III) Day2 | FP1: Antithrombin 3 (AT-III) Day12 | FQ1: Serummyoglobin Day2_From Start | FR1: Serummyoglobin Day1_From Start | FS1: Serummyoglobin Day_Unknown | FT1: Serummyoglobin Day1 | FU1: Serummyoglobin Day3 | FV1: Serummyoglobin Day15 | FW1: Serummyoglobin Day16 | FX1: D-Dimer Day_UnKnown | FY1: D-Dimer Day1 | FZ1: D-Dimer Day2 | GA1: D-Dimer Day4 | GB1: CH-50 Day_Unknown | GC1: Fibrinogen Day12_From Start | GD1: Fibrinogen Day11_From Start | GE1: Fibrinogen Day8_From Start | GF1: Fibrinogen Day7_From Start | GG1: Fibrinogen Day2_From Start | GH1: Fibrinogen Day1_From Start | GI1: Fibrinogen Day_Unknown | GJ1: Fibrinogen Day1 | GK1: Fibrinogen Day2 | GL1: Fibrinogen Day3 | GM1: Fibrinogen Day4 | GN1: Fibrinogen Day7 | GO1: Fibrinogen Day9 | GP1: Fibrinogen Day10 | GQ1: Fibrinogen Day11 | GR1: Fibrinogen Day12 | GS1: Fibrinogen Day13 | GT1: Fibrinogen Day15 | GU1: Fibrinogen Day16 | GV1: Fibrinogen Day22 | GW1: Fibrinogen Day55 | GX1: AT III Day_Unknown | GY1: Leukozyten Day64_From Start | GZ1: Leukozyten Day48_From Start | HA1: Leukozyten Day39_From Start | HB1: Leukozyten Day36_From Start | HC1: Leukozyten Day27_From Start | HD1: Leukozyten Day20_From Start | HE1: Leukozyten Day12_From Start | HF1: Leukozyten Day11_From Start | HG1: Leukozyten Day9_From Start | HH1: Leukozyten Day8_From Start | HI1: Leukozyten Day7_From Start | HJ1: Leukozyten Day6_From Start | HK1: Leukozyten Day5_From Start | HL1: Leukozyten Day4_From Start | HM1: Leukozyten Day3_From Start | HN1: Leukozyten Day2_From Start | HO1: Leukozyten Day1_From Start | HP1: Leukozyten Day_Unknown | HQ1: Leukozyten Day1 | HR1: Leukozyten Day2 | HS1: Leukozyten Day3 | HT1: Leukozyten Day4 | HU1: Leukozyten Day5 | HV1: Leukozyten Day6 | HW1: Leukozyten Day7 | HX1: Leukozyten Day8 | HY1: Leukozyten Day9 | HZ1: Leukozyten Day10 | IA1: Leukozyten Day11 | IB1: Leukozyten Day12 | IC1: Leukozyten Day13 | ID1: Leukozyten Day14 | IE1: Leukozyten Day15 | IF1: Leukozyten Day16 | IG1: Leukozyten Day17 | IH1: Leukozyten Day20 | II1: Leukozyten Day21 | IJ1: Leukozyten Day22 | IK1: Leukozyten Day23 | IL1: Leukozyten Day25 | IM1: Leukozyten Day27 | IN1: Leukozyten Day31 | IO1: Leukozyten Day33 | IP1: Leukozyten Day55 | IQ1: Leukozyten Day67 | IR1: Leukozyten Day74 | IS1: Leukozyten Day172 | IT1: GOT Day275_From Start | IU1: GOT Day114_From Start | IV1: GOT Day107_From Start | IW1: GOT Day105_From Start | IX1: GOT Day56_From Start | IY1: GOT Day36_From Start | IZ1: GOT Day26_From Start | JA1: GOT Day22_From Start | JB1: GOT Day20_From Start | JC1: GOT Day18_From Start | JD1: GOT Day13_From Start | JE1: GOT Day12_From Start | JF1: GOT Day11_From Start | JG1: GOT Day9_From Start | JH1: GOT Day8_From Start | JI1: GOT Day7_From Start | JJ1: GOT Day6_From Start | JK1: GOT Day5_From Start | JL1: GOT Day4_From Start | JM1: GOT Day3_From Start | JN1: GOT Day2_From Start | JO1: GOT Day1_From Start | JP1: GOT Day_Unknown | JQ1: GOT Day1 | JR1: GOT Day2 | JS1: GOT Day3 | JT1: GOT Day4 | JU1: GOT Day5 | JV1: GOT Day6 | JW1: GOT Day7 | JX1: GOT Day8 | JY1: GOT Day9 | JZ1: GOT Day10 | KA1: GOT Day11 | KB1: GOT Day12 | KC1: GOT Day13 | KD1: GOT Day14 | KE1: GOT Day15 | KF1: GOT Day16 | KG1: GOT Day17 | KH1: GOT Day18 | KI1: GOT Day19 | KJ1: GOT Day20 | KK1: GOT Day21 | KL1: GOT Day22 | KM1: GOT Day23 | KN1: GOT Day24 | KO1: GOT Day25 | KP1: GOT Day26 | KQ1: GOT Day27 | KR1: GOT Day28 | KS1: GOT Day31 | KT1: GOT Day32 | KU1: GOT Day33 | KV1: GOT Day34 | KW1: GOT Day35 | KX1: GOT Day36 | KY1: GOT Day37 | KZ1: GOT Day39 | LA1: GOT Day40 | LB1: GOT Day41 | LC1: GOT Day43 | LD1: GOT Day45 | LE1: GOT Day47 | LF1: GOT Day48 | LG1: GOT Day49 | LH1: GOT Day51 | LI1: GOT Day53 | LJ1: GOT Day54 | LK1: GOT Day55 | LL1: GOT Day56 | LM1: GOT Day58 | LN1: GOT Day61 | LO1: GOT Day62 | LP1: GOT Day66 | LQ1: GOT Day67 | LR1: GOT Day70 | LS1: GOT Day71 | LT1: GOT Day74 | LU1: GOT Day78 | LV1: GOT Day79 | LW1: GOT Day84 | LX1: GOT Day88 | LY1: GOT Day92 | LZ1: GOT Day96 | MA1: GOT Day99 | MB1: GOT Day103 | MC1: GOT Day107 | MD1: GOT Day110 | ME1: GOT Day163 | MF1: GPT Day275_From Start | MG1: GPT Day114_From Start | MH1: GPT Day107_From Start | MI1: GPT Day105_From Start | MJ1: GPT Day55_From Start | MK1: GPT Day54_From Start | ML1: GPT Day37_From Start | MM1: GPT Day36_From Start | MN1: GPT Day30_From Start | MO1: GPT Day28_From Start | MP1: GPT Day22_From Start | MQ1: GPT Day20_From Start | MR1: GPT Day18_From Start | MS1: GPT Day13_From Start | MT1: GPT Day12_From Start | MU1: GPT Day11_From Start | MV1: GPT Day9_From Start | MW1: GPT Day8_From Start | MX1: GPT Day7_From Start | MY1: GPT Day6_From Start | MZ1: GPT Day5_From Start | NA1: GPT Day4_From Start | NB1: GPT Day3_From Start | NC1: GPT Day2_From Start | ND1: GPT Day1_From Start | NE1: GPT Day_Unknown | NF1: GPT Day1 | NG1: GPT Day2 | NH1: GPT Day3 | NI1: GPT Day4 | NJ1: GPT Day5 | NK1: GPT Day6 | NL1: GPT Day7 | NM1: GPT Day8 | NN1: GPT Day9 | NO1: GPT Day10 | NP1: GPT Day11 | NQ1: GPT Day12 | NR1: GPT Day13 | NS1: GPT Day14 | NT1: GPT Day15 | NU1: GPT Day16 | NV1: GPT Day17 | NW1: GPT Day18 | NX1: GPT Day19 | NY1: GPT Day20 | NZ1: GPT Day21 | OA1: GPT Day22 | OB1: GPT Day23 | OC1: GPT Day24 | OD1: GPT Day25 | OE1: GPT Day26 | OF1: GPT Day27 | OG1: GPT Day28 | OH1: GPT Day31 | OI1: GPT Day33 | OJ1: GPT Day34 | OK1: GPT Day35 | OL1: GPT Day36 | OM1: GPT Day37 | ON1: GPT Day38 | OO1: GPT Day39 | OP1: GPT Day40 | OQ1: GPT Day42 | OR1: GPT Day43 | OS1: GPT Day44 | OT1: GPT Day46 | OU1: GPT Day47 | OV1: GPT Day48 | OW1: GPT Day49 | OX1: GPT Day51 | OY1: GPT Day53 | OZ1: GPT Day54 | PA1: GPT Day55 | PB1: GPT Day56 | PC1: GPT Day57 | PD1: GPT Day61 | PE1: GPT Day62 | PF1: GPT Day66 | PG1: GPT Day67 | PH1: GPT Day68 | PI1: GPT Day70 | PJ1: GPT Day71 | PK1: GPT Day74 | PL1: GPT Day78 | PM1: GPT Day79 | PN1: GPT Day84 | PO1: GPT Day88 | PP1: GPT Day92 | PQ1: GPT Day96 | PR1: GPT Day99 | PS1: GPT Day103 | PT1: GPT Day107 | PU1: GPT Day110 | PV1: GPT Day164 | PW1: GPT Day168 | PX1: GGT Day275_From Start | PY1: GGT Day114_From Start | PZ1: GGT Day105_From Start | QA1: GGT Day67_From Start | QB1: GGT Day55_From Start | QC1: GGT Day37_From Start | QD1: GGT Day36_From Start | QE1: GGT Day22_From Start | QF1: GGT Day20_From Start | QG1: GGT Day18_From Start | QH1: GGT Day12_From Start | QI1: GGT Day11_From Start | QJ1: GGT Day9_From Start | QK1: GGT Day8_From Start | QL1: GGT Day7_From Start | QM1: GGT Day6_From Start | QN1: GGT Day5_From Start | QO1: GGT Day4_From Start | QP1: GGT Day3_From Start | QQ1: GGT Day2_From Start | QR1: GGT Day1_From Start | QS1: GGT Day_Unknown | QT1: GGT Day1 | QU1: GGT Day2 | QV1: GGT Day3 | QW1: GGT Day4 | QX1: GGT Day5 | QY1: GGT Day6 | QZ1: GGT Day7 | RA1: GGT Day8 | RB1: GGT Day9 | RC1: GGT Day10 | RD1: GGT Day11 | RE1: GGT Day12 | RF1: GGT Day13 | RG1: GGT Day14 | RH1: GGT Day15 | RI1: GGT Day16 | RJ1: GGT Day17 | RK1: GGT Day18 | RL1: GGT Day19 | RM1: GGT Day20 | RN1: GGT Day21 | RO1: GGT Day22 | RP1: GGT Day23 | RQ1: GGT Day24 | RR1: GGT Day26 | RS1: GGT Day28 | RT1: GGT Day31 | RU1: GGT Day32 | RV1: GGT Day33 | RW1: GGT Day34 | RX1: GGT Day35 | RY1: GGT Day36 | RZ1: GGT Day37 | SA1: GGT Day40 | SB1: GGT Day43 | SC1: GGT Day44 | SD1: GGT Day48 | SE1: GGT Day49 | SF1: GGT Day50 | SG1: GGT Day51 | SH1: GGT Day53 | SI1: GGT Day55 | SJ1: GGT Day56 | SK1: GGT Day58 | SL1: GGT Day61 | SM1: GGT Day62 | SN1: GGT Day66 | SO1: GGT Day67 | SP1: GGT Day70 | SQ1: GGT Day74 | SR1: GGT Day78 | SS1: GGT Day79 | ST1: GGT Day82 | SU1: GGT Day86 | SV1: GGT Day92 | SW1: GGT Day99 | SX1: GGT Day103 | SY1: GGT Day110 | SZ1: LDH Day64_From Start | TA1: LDH Day13_From Start | TB1: LDH Day12_From Start | TC1: LDH Day11_From Start | TD1: LDH Day7_From Start | TE1: LDH Day6_From Start | TF1: LDH Day5_From Start | TG1: LDH Day4_From Start | TH1: LDH Day3_From Start | TI1: LDH Day2_From Start | TJ1: LDH Day1_From Start | TK1: LDH Day_Unknown | TL1: LDH Day1 | TM1: LDH Day2 | TN1: LDH Day3 | TO1: LDH Day4 | TP1: LDH Day5 | TQ1: LDH Day6 | TR1: LDH Day7 | TS1: LDH Day8 | TT1: LDH Day9 | TU1: LDH Day10 | TV1: LDH Day11 | TW1: LDH Day12 | TX1: LDH Day13 | TY1: LDH Day15 | TZ1: LDH Day16 | UA1: LDH Day17 | UB1: LDH Day18 | UC1: LDH Day22 | UD1: LDH Day24 | UE1: LDH Day28 | UF1: LDH Day21 | UG1: LDH Day33 | UH1: LDH Day36 | UI1: LDH Day55 | UJ1: LDH Day56 | UK1: LDH Day70 | UL1: GLDH Day275_From Start | UM1: GLDH Day_Unknown | UN1: GLDH Day1 | UO1: GLDH Day2 | UP1: GLDH Day3 | UQ1: GLDH Day4 | UR1: GLDH Day5 | US1: GLDH Day7 | UT1: GLDH Day11 | UU1: GLDH Day13 | UV1: GLDH Day15 | UW1: GLDH Day16 | UX1: GLDH Day19 | UY1: GLDH Day20 | UZ1: GLDH Day31 | VA1: GLDH Day32 | VB1: GLDH Day35 | VC1: GLDH Day49 | VD1: GLDH Day55 | VE1: GLDH Day67 | VF1: GLDH Day70 | VG1: GLDH Day79 | VH1: GLDH Day84 | VI1: GLDH Day103 | VJ1: Triglyceride Day22_From Start | VK1: Triglyceride Day2_From Start | VL1: Triglyceride Day1_From Start | VM1: Triglyceride Day_Unknown | VN1: Triglyceride Day1 | VO1: Triglyceride Day2 | VP1: Triglyceride Day4 | VQ1: Triglyceride Day5 | VR1: Triglyceride Day6 | VS1: Triglyceride Day14 | VT1: Triglyceride Day15 | VU1: Triglyceride Day16 | VV1: Triglyceride Day21 | VW1: Triglyceride Day25 | VX1: Triglyceride Day28 | VY1: Triglyceride Day46 | VZ1: Triglyceride Day58 | WA1: Triglyceride Day88 | WB1: Cholessterin Day55_From Start | WC1: Cholessterin Day1_From Start | WD1: Cholesterin Day_Unknown | WE1: Cholesterin Day1 | WF1: Cholesterin Day4 | WG1: Cholesterin Day5 | WH1: Cholesterin Day8 | WI1: Cholesterin Day14 | WJ1: Cholesterin Day15 | WK1: Cholesterin Day16 | WL1: Cholesterin Day18 | WM1: Cholesterin Day25 | WN1: Cholesterin Day88 | WO1: HDL Day_Unknown | WP1: HDL Day1 | WQ1: HDL Day12 | WR1: HDL Day14 | WS1: HDL Day25 | WT1: HDL Day58 | WU1: HDL Day88 | WV1: LDL Day_Unknown | WW1: LDL Day1 | WX1: LDL Day14 | WY1: LDL Day25 | WZ1: LDL Day58 | XA1: LDL Day88 | XB1: LDL/HDL Day_Unknown | XC1: Cholesterol/HDL Day_Unknown | XD1: Lymphozyten Day36_From Start | XE1: Lymphozyten Day22_From Start | XF1: Lymphozyten Day20_From Start | XG1: Lymphozyten Day12_From Start | XH1: Lymphozyten Day11_From Start | XI1: Lymphozyten Day7_From Start | XJ1: Lymphozyten Day6_From Start | XK1: Lymphozyten Day4_From Start | XL1: Lymphozyten Day_Unknown | XM1: Lymphozyten d1 | XN1: Lymphozyten d2 | XO1: Lymphozyten d3 | XP1: Lymphozyten d4 | XQ1: Lymphozyten d5 | XR1: Lymphozyten d6 | XS1: Lymphozyten d8 | XT1: Lymphozyten d9 | XU1: Lymphozyten d11 | XV1: Lymphozyten d13 | XW1: Lymphozyten d14 | XX1: Lymphozyten d15 | XY1: Lymphozyten d30 | XZ1: Lymphozyten d31 | YA1: Lymphozyten d33 | YB1: Lymphozyten d46 | YC1: Lymphozyten d66 | YD1: Lymphozyten d67 | YE1: Lymphozyten d84 | YF1: Lymphozyten d85 | YG1: Monocyten Day36_From Start | YH1: Monocyten Day22_From Start | YI1: Monocyten Day20_From Start | YJ1: Monocyten Day12_From Start | YK1: Monocyten Day7_From Start | YL1: Monocyten Day6_From Start | YM1: Monocyten Day_Unknown | YN1: Monocyten Day1 | YO1: Monocyten Day2 | YP1: Monocyten Day3 | YQ1: Monocyten Day5 | YR1: Monocyten Day6 | YS1: Monocyten Day9 | YT1: Monocyten Day14 | YU1: Monocyten Day15 | YV1: Monocyten Day31 | YW1: Monocyten Day67 | YX1: Monocyten Day84 | YY1: Hb Day72_From Start | YZ1: Hb Day64_From Start | ZA1: Hb Day56_From Start | ZB1: Hb Day43_From Start | ZC1: Hb Day38_From Start | ZD1: Hb Day36_From Start | ZE1: Hb Day26_From Start | ZF1: Hb Day22_From Start | ZG1: Hb Day21_From Start | ZH1: Hb Day20_From Start | ZI1: Hb Day14_From Start | ZJ1: Hb Day12_From Start | ZK1: Hb Day11_From Start | ZL1: Hb Day8_From Start | ZM1: Hb Day7_From Start | ZN1: Hb Day6_From Start | ZO1: Hb Day5_From Start | ZP1: Hb Day3_From Start | ZQ1: Hb Day2_From Start | ZR1: Hb Day1_From Start | ZS1: Hb Day_Unknown | ZT1: Hb Day1 | ZU1: Hb Day2 | ZV1: Hb Day3 | ZW1: Hb Day4 | ZX1: Hb Day5 | ZY1: Hb Day6 | ZZ1: Hb Day7 | AAA1: Hb Day8 | AAB1: Hb Day9 | AAC1: Hb Day10 | AAD1: Hb Day11 | AAE1: Hb Day12 | AAF1: Hb Day13 | AAG1: Hb Day14 | AAH1: Hb Day15 | AAI1: Hb Day16 | AAJ1: Hb Day17 | AAK1: Hb Day18 | AAL1: Hb Day21 | AAM1: Hb Day22 | AAN1: Hb Day23 | AAO1: Hb Day37 | AAP1: Hb Day31 | AAQ1: Hb Day55 | AAR1: Hb Day56 | AAS1: Hb Day66 | AAT1: Hb Day67 | AAU1: Hb Day70 | AAV1: Hb Day74 | AAW1: Hb Day124 | AAX1: Hb Day172 | AAY1: BloodBilirubin Day_Unknown | AAZ1: BloodBilirubin Day7_From Start | ABA1: BloodBilirubin Day2_From Start | ABB1: BloodBilirubin Day1 | ABC1: BloodBilirubin Day2 | ABD1: BloodBilirubin Day3 | ABE1: BloodBilirubin Day4 | ABF1: BloodBilirubin Day5 | ABG1: BloodBilirubin Day6 | ABH1: BloodBilirubin Day7 | ABI1: BloodBilirubin Day8 | ABJ1: BloodBilirubin Day9 | ABK1: BloodBilirubin Day10 | ABL1: BloodBilirubin Day12 | ABM1: BloodBilirubin Day13 | ABN1: BloodBilirubin Day14 | ABO1: BloodBilirubin Day17 | ABP1: BloodBilirubin Day18 | ABQ1: BloodBilirubin Day22 | ABR1: BloodBilirubin Day36 | ABS1: TotalBilirubin Day107_From Start | ABT1: TotalBilirubin Day64_From Start | ABU1: TotalBilirubin Day22_From Start | ABV1: TotalBilirubin Day12_From Start | ABW1: TotalBilirubin Day11_From Start | ABX1: TotalBilirubin Day8_From Start | ABY1: TotalBilirubin Day7_From Start | ABZ1: TotalBilirubin Day6_From Start | ACA1: TotalBilirubin Day5_From Start | ACB1: TotalBilirubin Day4_From Start | ACC1: TotalBilirubin Day3_From Start | ACD1: TotalBilirubin Day2_From Start | ACE1: TotalBilirubin Day1_From Start | ACF1: TotalBilirubin Day_Unknown | ACG1: TotalBilirubin Day1 | ACH1: TotalBilirubin Day2 | ACI1: TotalBilirubin Day3 | ACJ1: TotalBilirubin Day4 | ACK1: TotalBilirubin Day5 | ACL1: TotalBilirubin Day6 | ACM1: TotalBilirubin Day7 | ACN1: TotalBilirubin Day8 | ACO1: TotalBilirubin Day9 | ACP1: TotalBilirubin Day10 | ACQ1: TotalBilirubin Day11 | ACR1: TotalBilirubin Day12 | ACS1: TotalBilirubin Day13 | ACT1: TotalBilirubin Day14 | ACU1: TotalBilirubin Day15 | ACV1: TotalBilirubin Day16 | ACW1: TotalBilirubin Day17 | ACX1: TotalBilirubin Day18 | ACY1: TotalBilirubin Day19 | ACZ1: TotalBilirubin Day20 | ADA1: TotalBilirubin Day21 | ADB1: TotalBilirubin Day22 | ADC1: TotalBilirubin Day23 | ADD1: TotalBilirubin Day24 | ADE1: TotalBilirubin Day26 | ADF1: TotalBilirubin Day28 | ADG1: TotalBilirubin Day31 | ADH1: TotalBilirubin Day32 | ADI1: TotalBilirubin Day33 | ADJ1: TotalBilirubin Day34 | ADK1: TotalBilirubin Day35 | ADL1: TotalBilirubin Day36 | ADM1: TotalBilirubin Day37 | ADN1: TotalBilirubin Day44 | ADO1: TotalBilirubin Day46 | ADP1: TotalBilirubin Day47 | ADQ1: TotalBilirubin Day48 | ADR1: TotalBilirubin Day49 | ADS1: TotalBilirubin Day51 | ADT1: TotalBilirubin Day53 | ADU1: TotalBilirubin Day54 | ADV1: TotalBilirubin Day55 | ADW1: TotalBilirubin Day56 | ADX1: TotalBilirubin Day58 | ADY1: TotalBilirubin Day66 | ADZ1: TotalBilirubin Day67 | AEA1: TotalBilirubin Day78 | AEB1: TotalBilirubin Day79 | AEC1: TotalBilirubin Day84 | AED1: TotalBilirubin Day92 | AEE1: TotalBilirubin Day96 | AEF1: TotalBilirubin Day103 | AEG1: TotalBilirubin Day164 | AEH1: DirectBilirubin Day64_From Start | AEI1: DirectBilirubin Day_Unknown | AEJ1: DirectBilirubin Day1 | AEK1: DirectBilirubin Day2 | AEL1: DirectBilirubin Day3 | AEM1: DirectBilirubin Day4 | AEN1: DirectBilirubin Day5 | AEO1: DirectBilirubin Day6 | AEP1: DirectBilirubin Day7 | AEQ1: DirectBilirubin Day8 | AER1: DirectBilirubin Day10 | AES1: DirectBilirubin Day11 | AET1: DirectBilirubin Day12 | AEU1: DirectBilirubin Day15 | AEV1: DirectBilirubin Day16 | AEW1: DirectBilirubin Day17 | AEX1: DirectBilirubin Day18 | AEY1: DirectBilirubin Day19 | AEZ1: DirectBilirubin Day20 | AFA1: DirectBilirubin Day23 | AFB1: DirectBilirubin Day24 | AFC1: DirectBilirubin Day26 | AFD1: DirectBilirubin Day31 | AFE1: DirectBilirubin Day35 | AFF1: DirectBilirubin Day49 | AFG1: DirectBilirubin Day55 | AFH1: DirectBilirubin Day92 | AFI1: DirectBilirubin Day103 | AFJ1: Gesamteiweiß Day11_From Start | AFK1: Gesamteiweiß Day2_From Start | AFL1: Gesamteiweiß Day_Unknown | AFM1: Gesamteiweiß Day1 | AFN1: Gesamteiweiß Day2 | AFO1: Gesamteiweiß Day4 | AFP1: Gesamteiweiß Day5 | AFQ1: Gesamteiweiß Day6 | AFR1: Gesamteiweiß Day9 | AFS1: Gesamteiweiß Day10 | AFT1: Gesamteiweiß Day11 | AFU1: Gesamteiweiß Day12 | AFV1: Gesamteiweiß Day15 | AFW1: Gesamteiweiß Day16 | AFX1: Gesamteiweiß Day24 | AFY1: Gesamteiweiß Day66 | AFZ1: AP Day1080_From Start | AGA1: AP Day107_From Start | AGB1: AP Day37_From Start | AGC1: AP Day36_From Start | AGD1: AP Day30_From Start | AGE1: AP Day22_From Start | AGF1: AP Day20_From Start | AGG1: AP Day18_From Start | AGH1: AP Day14_From Start | AGI1: AP Day13_From Start | AGJ1: AP Day12_From Start | AGK1: AP Day11_From Start | AGL1: AP Day18_From Start | AGM1: AP Day7_From Start | AGN1: AP Day6_From Start | AGO1: AP Day5_From Start | AGP1: AP Day4_From Start | AGQ1: AP Day3_From Start | AGR1: AP Day2_From Start | AGS1: AP Day1_From Start | AGT1: AP Day_Unknown | AGU1: AP Day1 | AGV1: AP Day2 | AGW1: AP Day3 | AGX1: AP Day4 | AGY1: AP Day5 | AGZ1: AP Day6 | AHA1: AP Day7 | AHB1: AP Day8 | AHC1: AP Day9 | AHD1: AP Day10 | AHE1: AP Day11 | AHF1: AP Day12 | AHG1: AP Day13 | AHH1: AP Day14 | AHI1: AP Day15 | AHJ1: AP Day16 | AHK1: AP Day17 | AHL1: AP Day18 | AHM1: AP Day19 | AHN1: AP Day20 | AHO1: AP Day21 | AHP1: AP Day22 | AHQ1: AP Day23 | AHR1: AP Day24 | AHS1: AP Day25 | AHT1: AP Day26 | AHU1: AP Day28 | AHV1: AP Day31 | AHW1: AP Day34 | AHX1: AP Day36 | AHY1: AP Day31 | AHZ1: AP Day33 | AIA1: AP Day34 | AIB1: AP Day35 | AIC1: AP Day40 | AID1: AP Day42 | AIE1: AP Day44 | AIF1: AP Day47 | AIG1: AP Day48 | AIH1: AP Day49 | AII1: AP Day53 | AIJ1: AP Day55 | AIK1: AP Day56 | AIL1: AP Day58 | AIM1: AP Day61 | AIN1: AP Day62 | AIO1: AP Day67 | AIP1: AP Day70 | AIQ1: AP Day79 | AIR1: AP Day84 | AIS1: AP Day88 | AIT1: AP Day92 | AIU1: AP Day103 | AIV1: AP Day164 | AIW1: Cholesterinase Day11_From Start | AIX1: Cholesterinase Day_Unknown | AIY1: Cholesterinase Day1 | AIZ1: Cholesterinase Day2 | AJA1: Cholesterinase Day3 | AJB1: Cholesterinase Day4 | AJC1: Cholesterinase Day5 | AJD1: Cholesterinase Day6 | AJE1: Cholesterinase Day7 | AJF1: Cholesterinase Day8 | AJG1: Cholesterinase Day9 | AJH1: Cholesterinase Day10 | AJI1: Cholesterinase Day12 | AJJ1: Cholesterinase Day15 | AJK1: Cholesterinase Day16 | AJL1: Cholesterinase Day28 | AJM1: Cholesterinase Day35 | AJN1: Cholesterinase Day47 | AJO1: Cholesterinase Day66 | AJP1: Cholesterinase Day79 | AJQ1: Cholesterinase Day103 | AJR1: Kreatinin Day64_From Start | AJS1: Kreatinin Day36_From Start | AJT1: Kreatinin Day20_From Start | AJU1: Kreatinin Day12_From Start | AJV1: Kreatinin Day11_From Start | AJW1: Kreatinin Day8_From Start | AJX1: Kreatinin Day7_From Start | AJY1: Kreatinin Day6_From Start | AJZ1: Kreatinin Day5_From Start | AKA1: Kreatinin Day4_From Start | AKB1: Kreatinin Day3_From Start | AKC1: Kreatinin Day2_From Start | AKD1: Kreatinin Day1_From Start | AKE1: Kreatinin Day_Unknown | AKF1: Kreatinin Day1 | AKG1: Kreatinin Day2 | AKH1: Kreatinin Day3 | AKI1: Kreatinin Day4 | AKJ1: Kreatinin Day5 | AKK1: Kreatinin Day6 | AKL1: Kreatinin Day7 | AKM1: Kreatinin Day8 | AKN1: Kreatinin Day9 | AKO1: Kreatinin Day10 | AKP1: Kreatinin Day11 | AKQ1: Kreatinin Day12 | AKR1: Kreatinin Day13 | AKS1: Kreatinin Day14 | AKT1: Kreatinin Day15 | AKU1: Kreatinin Day17 | AKV1: Kreatinin Day18 | AKW1: Kreatinin Day21 | AKX1: Kreatinin Day22 | AKY1: Kreatinin Day24 | AKZ1: Kreatinin Day25 | ALA1: Kreatinin Day28 | ALB1: Kreatinin Day31 | ALC1: Kreatinin Day33 | ALD1: Kreatinin Day34 | ALE1: Kreatinin Day35 | ALF1: Kreatinin Day55 | ALG1: Kreatinin Day79 | ALH1: Kreatinin Day85 | ALI1: Kreatinkinase Day_Unknown | ALJ1: Kreatinkinase Day1 | ALK1: Kreatinkinase Day4 | ALL1: Amylase Day3_From Start | ALM1: Amylase Day2_From Start | ALN1: Amylase Day1_From Start | ALO1: Amylase Day_Unknown | ALP1: Amylase Day1 | ALQ1: Amylase Day2 | ALR1: Amylase Day3 | ALS1: Amylase Day4 | ALT1: Amylase Day5 | ALU1: Amylase Day6 | ALV1: Amylase Day8 | ALW1: Amylase Day9 | ALX1: Amylase Day11 | ALY1: Amylase Day12 | ALZ1: Amylase Day14 | AMA1: Amylase Day15 | AMB1: Amylase Day16 | AMC1: Amylase Day21 | AMD1: Amylase Day31 | AME1: Amylase Day35 | AMF1: Amylase Day37 | AMG1: Amylase Day84 | AMH1: Lipase Day7_From Start | AMI1: Lipase Day6_From Start | AMJ1: Lipase Day3_From Start | AMK1: Lipase Day2_From Start | AML1: Lipase Day1_From Start | AMM1: Lipase Day_Unknown | AMN1: Lipase Day1 | AMO1: Lipase Day2 | AMP1: Lipase Day3 | AMQ1: Lipase Day4 | AMR1: Lipase Day5 | AMS1: Lipase Day6 | AMT1: Lipase Day8 | AMU1: Lipase Day9 | AMV1: Lipase Day10 | AMW1: Lipase Day11 | AMX1: Lipase Day13 | AMY1: Lipase Day14 | AMZ1: Lipase Day15 | ANA1: Lipase Day16 | ANB1: Lipase Day17 | ANC1: Lipase Day18 | AND1: Lipase Day21 | ANE1: Lipase Day31 | ANF1: Lipase Day31 | ANG1: Lipase Day34 | ANH1: Lipase Day35 | ANI1: Lipase Day48 | ANJ1: Lipase Day49 | ANK1: Lipase Day58 | ANL1: Lipase Day67 | ANM1: Lipase Day66 | ANN1: Lipase Day84 | ANO1: CRP Day12_From Start | ANP1: CRP Day11_From Start | ANQ1: CRP Day8_From Start | ANR1: CRP Day7_From Start | ANS1: CRP Day6_From Start | ANT1: CRP Day5_From Start | ANU1: CRP Day3_From Start | ANV1: CRP Day2_From Start | ANW1: CRP Day1_From Start | ANX1: CRP Day_Unknown | ANY1: CRP Day1 | ANZ1: CRP Day2 | AOA1: CRP Day3 | AOB1: CRP Day4 | AOC1: CRP Day5 | AOD1: CRP Day6 | AOE1: CRP Day7 | AOF1: CRP Day8 | AOG1: CRP Day9 | AOH1: CRP Day10 | AOI1: CRP Day11 | AOJ1: CRP Day12 | AOK1: CRP Day13 | AOL1: CRP Day14 | AOM1: CRP Day15 | AON1: CRP Day16 | AOO1: CRP Day17 | AOP1: CRP Day18 | AOQ1: CRP Day20 | AOR1: CRP Day21 | AOS1: CRP Day23 | AOT1: CRP Day24 | AOU1: CRP Day28 | AOV1: CRP Day36 | AOW1: CRP Day44 | AOX1: CRP Day35 | AOY1: CRP Day66 | AOZ1: CRP Day74 | APA1: CRP Day79 | APB1: CRP Day172 | APC1: Harnstoff Day11_From Start | APD1: Harnstoff Day8_From Start | APE1: Harnstoff Day7_From Start | APF1: Harnstoff Day6_From Start | APG1: Harnstoff Day5_From Start | APH1: Harnstoff Day3_From Start | API1: Harnstoff Day2_From Start | APJ1: Harnstoff Day1_From Start | APK1: Harnstoff Day_Unknown | APL1: Harnstoff Day1 | APM1: Harnstoff Day2 | APN1: Harnstoff Day3 | APO1: Harnstoff Day4 | APP1: Harnstoff Day6 | APQ1: Harnstoff Day7 | APR1: Harnstoff Day9 | APS1: Harnstoff Day10 | APT1: Harnstoff Day11 | APU1: Harnstoff Day13 | APV1: Harnstoff Day14 | APW1: Harnstoff Day15 | APX1: Harnstoff Day16 | APY1: Harnstoff Day17 | APZ1: Harnstoff Day22 | AQA1: Harnstoff Day25 | AQB1: Harnstoff Day28 | AQC1: Harnstoff Day31 | AQD1: Harnstoff Day34 | AQE1: Harnstoff Day55 | AQF1: Harnstoff Day66 | AQG1: Harnsäure Day64_From Start | AQH1: Harnsäure Day64_From Start | AQI1: Harnsäure Day64_From Start | AQJ1: Harnsäure Day64_From Start | AQK1: Harnsäure Day64_From Start | AQL1: Harnsäure Day_Unknown | AQM1: Harnsäure Day1 | AQN1: Harnsäure Day2 | AQO1: Harnsäure Day3 | AQP1: Harnsäure Day4 | AQQ1: Harnsäure Day7 | AQR1: Harnsäure Day9 | AQS1: Harnsäure Day10 | AQT1: Harnsäure Day14 | AQU1: Harnsäure Day15 | AQV1: Harnsäure Day15 | AQW1: Harnsäure Day28 | AQX1: Erythrozyten Day36_From Start | AQY1: Erythrozyten Day22_From Start | AQZ1: Erythrozyten Day20_From Start | ARA1: Erythrozyten Day12_From Start | ARB1: Erythrozyten Day11_From Start | ARC1: Erythrozyten Day8_From Start | ARD1: Erythrozyten Day7_From Start | ARE1: Erythrozyten Day6_From Start | ARF1: Erythrozyten Day5_From Start | ARG1: Erythrozyten Day3_From Start | ARH1: Erythrozyten Day2_From Start | ARI1: Erythrozyten Day1_From Start | ARJ1: Erythrozyten Day_Unknown | ARK1: Erythrozyten Day1 | ARL1: Erythrozyten Day2 | ARM1: Erythrozyten Day3 | ARN1: Erythrozyten Day4 | ARO1: Erythrozyten Day5 | ARP1: Erythrozyten Day6 | ARQ1: Erythrozyten Day7 | ARR1: Erythrozyten Day8 | ARS1: Erythrozyten Day9 | ART1: Erythrozyten Day10 | ARU1: Erythrozyten Day11 | ARV1: Erythrozyten Day12 | ARW1: Erythrozyten Day13 | ARX1: Erythrozyten Day14 | ARY1: Erythrozyten Day15 | ARZ1: Erythrozyten Day16 | ASA1: Erythrozyten Day22 | ASB1: Erythrozyten Day25 | ASC1: Erythrozyten Day31 | ASD1: Erythrozyten Day66 | ASE1: Erythrozyten Day67 | ASF1: Erythrozyten Day70 | ASG1: ESR Day_Unknown | ASH1: ESR Day4 | ASI1: Thrombozyten Day36_From Start | ASJ1: Thrombozyten Day20_From Start | ASK1: Thrombozyten Day12_From Start | ASL1: Thrombozyten Day11_From Start | ASM1: Thrombozyten Day9_From Start | ASN1: Thrombozyten Day8_From Start | ASO1: Thrombozyten Day7_From Start | ASP1: Thrombozyten Day6_From Start | ASQ1: Thrombozyten Day5_From Start | ASR1: Thrombozyten Day3_From Start | ASS1: Thrombozyten Day2_From Start | AST1: Thrombozyten Day1_From Start | ASU1: Thrombozyten Day_Unknown | ASV1: Thrombozyten Day1 | ASW1: Thrombozyten Day2 | ASX1: Thrombozyten Day3 | ASY1: Thrombozyten Day4 | ASZ1: Thrombozyten Day5 | ATA1: Thrombozyten Day6 | ATB1: Thrombozyten Day7 | ATC1: Thrombozyten Day8 | ATD1: Thrombozyten Day9 | ATE1: Thrombozyten Day10 | ATF1: Thrombozyten Day11 | ATG1: Thrombozyten Day12 | ATH1: Thrombozyten Day13 | ATI1: Thrombozyten Day14 | ATJ1: Thrombozyten Day15 | ATK1: Thrombozyten Day16 | ATL1: Thrombozyten Day17 | ATM1: Thrombozyten Day21 | ATN1: Thrombozyten Day22 | ATO1: Thrombozyten Day23 | ATP1: Thrombozyten Day24 | ATQ1: Thrombozyten Day25 | ATR1: Thrombozyten Day27 | ATS1: Thrombozyten Day31 | ATT1: Thrombozyten Day31 | ATU1: Thrombozyten Day34 | ATV1: Thrombozyten Day55 | ATW1: Thrombozyten Day66 | ATX1: Thrombozyten Day67 | ATY1: Thrombozyten Day70 | ATZ1: Thrombozyten Day94 | AUA1: Thrombozyten Day84 | AUB1: Thrombozyten Day85 | AUC1: Haptoglobin Day_Unknown | AUD1: Haptoglobin Day1 | AUE1: Haptoglobin Day2 | AUF1: Haptoglobin Day4 | AUG1: Haptoglobin Day5 | AUH1: BSG Day12_From Start | AUI1: BSG Day7_From Start | AUJ1: BSG Day_Unknown | AUK1: BSG Day1 | AUL1: BSG Day2 | AUM1: BSG Day9 | AUN1: BSG Day11 | AUO1: BSG Day12 | AUP1: Monozyten Day11_From Start | AUQ1: Monozyten Day_Unknown | AUR1: Monozyten Day1 | AUS1: Monozyten Day6 | AUT1: Monozyten Day33 | AUU1: Monozyten Day85 | AUV1: EosinophileDay36_From Start | AUW1: EosinophileDay20_From Start | AUX1: EosinophileDay12_From Start | AUY1: EosinophileDay11_From Start | AUZ1: EosinophileDay7_From Start | AVA1: EosinophileDay6_From Start | AVB1: EosinophileDay_Unknown | AVC1: EosinophileDay1 | AVD1: EosinophileDay2 | AVE1: EosinophileDay3 | AVF1: EosinophileDay4 | AVG1: EosinophileDay5 | AVH1: EosinophileDay6 | AVI1: EosinophileDay7 | AVJ1: EosinophileDay8 | AVK1: EosinophileDay9 | AVL1: EosinophileDay10 | AVM1: EosinophileDay11 | AVN1: Neutrophile Day48_From Start | AVO1: Neutrophile Day36_From Start | AVP1: Neutrophile Day22_From Start | AVQ1: Neutrophile Day20_From Start | AVR1: Neutrophile Day12_From Start | AVS1: Neutrophile Day9_From Start | AVT1: Neutrophile Day7_From Start | AVU1: Neutrophile Day6_From Start | AVV1: Neutrophile Day_Unknown | AVW1: Neutrophile Day1 | AVX1: Neutrophile Day2 | AVY1: Neutrophile Day3 | AVZ1: Neutrophile Day5 | AWA1: Neutrophile Day6 | AWB1: Neutrophile Day9 | AWC1: Neutrophile Day14 | AWD1: Neutrophile Day15 | AWE1: Neutrophile Day32 | AWF1: Neutrophile Day31 | AWG1: Neutrophile Day33 | AWH1: Neutrophile Day46 | AWI1: Neutrophile Day67 | AWJ1: Neutrophile Day84 | AWK1: Neutrophile Day85 | AWL1: Basophile Day36_From Start | AWM1: Basophile Day20_From Start | AWN1: Basophile Day12_From Start | AWO1: Basophile Day11_From Start | AWP1: Basophile Day7_From Start | AWQ1: Basophile Day6_From Start | AWR1: Basophile Day_Unknown | AWS1: Basophile Day1 | AWT1: Basophile Day2 | AWU1: Basophile Day3 | AWV1: Basophile Day9 | AWW1: Basophile Day15 | AWX1: Basophile Day31 | AWY1: Basophile Day67 | AWZ1: Basophile Day84 | AXA1: Basophile Day85 | AXB1: Albumin Day11_From Start | AXC1: Albumin Day8_From Start | AXD1: Albumin Day2_From Start | AXE1: Albumin Day1_From Start | AXF1: Albumin Day_Unknown | AXG1: Albumin Day1 | AXH1: Albumin Day2 | AXI1: Albumin Day3 | AXJ1: Albumin Day4 | AXK1: Albumin Day5 | AXL1: Albumin Day6 | AXM1: Albumin Day12 | AXN1: Albumin Day13 | AXO1: Albumin Day14 | AXP1: Albumin Day16 | AXQ1: Albumin Day17 | AXR1: Albumin Day24 | AXS1: Albumin Day25 | AXT1: Albumin Day55 | AXU1: Albumin Day70 | AXV1: Albumin Day92 | AXW1: GGTP Day_Unknown | AXX1: GGTP Day1 | AXY1: GGTP Day3 | AXZ1: gammaGlobulin Day5 | AYA1: gammaGlobulin Day12 | AYB1: alphaGlobulin Day_Unknown | AYC1: alphaGlobulin Day1 | AYD1: alphaGlobulin Day3 | AYE1: phBlut Day_Unknown | AYF1: phBlut Day1 | AYG1: phBlut Day2 | AYH1: phBlut Day3 | AYI1: phBlut Day4 | AYJ1: phBlut Day6 | AYK1: phBlut Day7 | AYL1: phBlut Day8 | AYM1: phBlut Day9 | AYN1: phBlut Day9 | AYO1: BaseExcess Day_Unknown | AYP1: BaseExcess Day1 | AYQ1: BaseExcess Day2 | AYR1: BaseExcess Day3 | AYS1: BaseExcess Day7 | AYT1: BaseExcess Day8 | AYU1: Bicarbonat Day_Unknown | AYV1: Bicarbonat Day1 | AYW1: Bicarbonat Day2 | AYX1: Bicarbonat Day3 | AYY1: Bicarbonat Day4 | AYZ1: Bicarbonat Day6 | AZA1: Bicarbonat Day7 | AZB1: Bicarbonat Day8 | AZC1: Bicarbonat Day10 | AZD1: Sauerstoffpartialdruck Day_Unknown | AZE1: Sauerstoffpartialdruck Day1 | AZF1: Sauerstoffpartialdruck Day2 | AZG1: Sauerstoffpartialdruck Day3 | AZH1: Sauerstoffpartialdruck Day7 | AZI1: Kohlendioxidpartialdruck Day_Unknown | AZJ1: Kohlendioxidpartialdruck Day1 | AZK1: Kohlendioxidpartialdruck Day2 | AZL1: Kohlendioxidpartialdruck Day3 | AZM1: Kohlendioxidpartialdruck Day4 | AZN1: Kohlendioxidpartialdruck Day6 | AZO1: Kohlendioxidpartialdruck Day7 | AZP1: Kohlendioxidpartialdruck Day8 | AZQ1: Kohlendioxidpartialdruck Day10 | AZR1: Sauerstoffsättigung Day_Unknown | AZS1: Sauerstoffsättigung Day2 | AZT1: Sauerstoffsättigung Day3 | AZU1: Sauerstoffsättigung Day7 | AZV1: Hämatokrit Day64_From Start | AZW1: Hämatokrit Day56_From Start | AZX1: Hämatokrit Day36_From Start | AZY1: Hämatokrit Day26_From Start | AZZ1: Hämatokrit Day22_From Start | BAA1: Hämatokrit Day20_From Start | BAB1: Hämatokrit Day12_From Start | BAC1: Hämatokrit Day11_From Start | BAD1: Hämatokrit Day8_From Start | BAE1: Hämatokrit Day7_From Start | BAF1: Hämatokrit Day6_From Start | BAG1: Hämatokrit Day5_From Start | BAH1: Hämatokrit Day3_From Start | BAI1: Hämatokrit Day2_From Start | BAJ1: Hämatokrit Day1_From Start | BAK1: Hämatokrit Day_Unknown | BAL1: Hämatokrit Day1 | BAM1: Hämatokrit Day2 | BAN1: Hämatokrit Day3 | BAO1: Hämatokrit Day4 | BAP1: Hämatokrit Day5 | BAQ1: Hämatokrit Day6 | BAR1: Hämatokrit Day7 | BAS1: Hämatokrit Day8 | BAT1: Hämatokrit Day9 | BAU1: Hämatokrit Day10 | BAV1: Hämatokrit Day11 | BAW1: Hämatokrit Day12 | BAX1: Hämatokrit Day13 | BAY1: Hämatokrit Day15 | BAZ1: Hämatokrit Day16 | BBA1: Hämatokrit Day18 | BBB1: Hämatokrit Day21 | BBC1: Hämatokrit Day22 | BBD1: Hämatokrit Day23 | BBE1: Hämatokrit Day24 | BBF1: Hämatokrit Day25 | BBG1: Hämatokrit Day27 | BBH1: Hämatokrit Day31 | BBI1: Hämatokrit Day36 | BBJ1: Hämatokrit Day55 | BBK1: Hämatokrit Day57 | BBL1: Hämatokrit Day66 | BBM1: Hämatokrit Day67 | BBN1: Hämatokrit Day70 | BBO1: Hämatokrit Day84 | BBP1: Hämatokrit Day85 | BBQ1: Hämatokrit Day124 | BBR1: MCV Day36_From Start | BBS1: MCV Day20_From Start | BBT1: MCV Day12_From Start | BBU1: MCV Day11_From Start | BBV1: MCV Day9_From Start | BBW1: MCV Day8_From Start | BBX1: MCV Day7_From Start | BBY1: MCV Day6_From Start | BBZ1: MCV Day3_From Start | BCA1: MCV Day2_From Start | BCB1: MCV Day1_From Start | BCC1: MCV Day_Unknown | BCD1: MCV Day1 | BCE1: MCV Day2 | BCF1: MCV Day3 | BCG1: MCV Day4 | BCH1: MCV Day5 | BCI1: MCV Day6 | BCJ1: MCV Day7 | BCK1: MCV Day9 | BCL1: MCV Day10 | BCM1: MCV Day11 | BCN1: MCV Day12 | BCO1: MCV Day15 | BCP1: MCV Day16 | BCQ1: MCV Day21 | BCR1: MCV Day23 | BCS1: MCV Day25 | BCT1: MCV Day31 | BCU1: MCV Day55 | BCV1: MCV Day67 | BCW1: MCV Day84 | BCX1: MCV Day85 | BCY1: MCH Day36_From Start | BCZ1: MCH Day20_From Start | BDA1: MCH Day12_From Start | BDB1: MCH Day11_From Start | BDC1: MCH Day8_From Start | BDD1: MCH Day7_From Start | BDE1: MCH Day6_From Start | BDF1: MCH Day3_From Start | BDG1: MCH Day2_From Start | BDH1: MCH Day_From Start | BDI1: MCH Day_Unknown | BDJ1: MCH Day1 | BDK1: MCH Day2 | BDL1: MCH Day3 | BDM1: MCH Day4 | BDN1: MCH Day5 | BDO1: MCH Day6 | BDP1: MCH Day7 | BDQ1: MCH Day9 | BDR1: MCH Day10 | BDS1: MCH Day11 | BDT1: MCH Day12 | BDU1: MCH Day15 | BDV1: MCH Day16 | BDW1: MCH Day25 | BDX1: MCH Day31 | BDY1: MCH Day67 | BDZ1: MCH Day84 | BEA1: MCH Day85 | BEB1: MCHC Day36_From Start | BEC1: MCHC Day20_From Start | BED1: MCHC Day12_From Start | BEE1: MCHC Day11_From Start | BEF1: MCHC Day8_From Start | BEG1: MCHC Day7_From Start | BEH1: MCHC Day6_From Start | BEI1: MCHC Day3_From Start | BEJ1: MCHC Day2_From Start | BEK1: MCHC Day1_From Start | BEL1: MCHC Day_Unknown | BEM1: MCHC Day1 | BEN1: MCHC Day2 | BEO1: MCHC Day3 | BEP1: MCHC Day4 | BEQ1: MCHC Day5 | BER1: MCHC Day6 | BES1: MCHC Day7 | BET1: MCHC Day9 | BEU1: MCHC Day10 | BEV1: MCHC Day11 | BEW1: MCHC Day12 | BEX1: MCHC Day15 | BEY1: MCHC Day16 | BEZ1: MCHC Day22 | BFA1: MCHC Day25 | BFB1: MCHC Day31 | BFC1: MCHC Day67 | BFD1: MCHC Day84 | BFE1: MCHC Day85 | BGH1: Natrium Day11_From Start | BGI1: Natrium Day9_From Start | BGJ1: Natrium Day8_From Start | BGK1: Natrium Day7_From Start | BGL1: Natrium Day5_From Start | BGM1: Natrium Day3_From Start | BGN1: Natrium Day2_From Start | BGO1: Natrium Day1_From Start | BGP1: Natrium Day_Unknown | BGQ1: Natrium Day1 | BGR1: Natrium Day2 | BGS1: Natrium Day3 | BGT1: Natrium Day4 | BGU1: Natrium Day5 | BGV1: Natrium Day6 | BGW1: Natrium Day7 | BGX1: Natrium Day8 | BGY1: Natrium Day9 | BGZ1: Natrium Day10 | BHA1: Natrium Day11 | BHB1: Natrium Day12 | BHC1: Natrium Day13 | BHD1: Natrium Day14 | BHE1: Natrium Day15 | BHF1: Natrium Day17 | BHG1: Natrium Day21 | BHH1: Natrium Day22 | BHI1: Natrium Day28 | BHJ1: Natrium Day34 | BHK1: Natrium Day55 | BHL1: Natrium Day66 | BHM1: Kalium Day12_From Start | BHN1: Kalium Day11_From Start | BHO1: Kalium Day9_From Start | BHP1: Kalium Day8_From Start | BHQ1: Kalium Day7_From Start | BHR1: Kalium Day5_From Start | BHS1: Kalium Day3_From Start | BHT1: Kalium Day2_From Start | BHU1: Kalium Day1_From Start | BHV1: Kalium Day_Unknown | BHW1: Kalium Day1 | BHX1: Kalium Day2 | BHY1: Kalium Day3 | BHZ1: Kalium Day4 | BIA1: Kalium Day5 | BIB1: Kalium Day6 | BIC1: Kalium Day7 | BID1: Kalium Day8 | BIE1: Kalium Day9 | BIF1: Kalium Day10 | BIG1: Kalium Day11 | BIH1: Kalium Day12 | BII1: Kalium Day13 | BIJ1: Kalium Day14 | BIK1: Kalium Day15 | BIL1: Kalium Day21 | BIM1: Kalium Day22 | BIN1: Kalium Day34 | BIO1: Kalium Day55 | BIP1: Kalium Day66 | BIQ1: Kalzium Day12_From Start | BIR1: Kalzium Day11_From Start | BIS1: Kalzium Day8_From Start | BIT1: Kalzium Day7_From Start | BIU1: Kalzium Day5_From Start | BIV1: Kalzium Day3_From Start | BIW1: Kalzium Day2_From Start | BIX1: Kalzium Day1_From Start | BIY1: Kalzium Day_Unknown | BIZ1: Kalzium Day1 | BJA1: Kalzium Day2 | BJB1: Kalzium Day3 | BJC1: Kalzium Day4 | BJD1: Kalzium Day5 | BJE1: Kalzium Day6 | BJF1: Kalzium Day7 | BJG1: Kalzium Day8 | BJH1: Kalzium Day9 | BJI1: Kalzium Day10 | BJJ1: Kalzium Day11 | BJK1: Kalzium Day15 | BJL1: Kalzium Day17 | BJM1: Kalzium Day22 | BJN1: Kalzium Day24 | BJO1: Kalzium Day34 | BJP1: Magnesium Day11_From Start | BJQ1: Magnesium Day8_From Start | BJR1: Magnesium Day2_From Start | BJS1: Magnesium Day1_From Start | BJT1: Magnesium Day_Unknown | BJU1: Magnesium Day1 | BJV1: Magnesium Day2 | BJW1: Magnesium Day3 | BJX1: Magnesium Day4 | BJY1: Chlorid Day2_From Start | BJZ1: Chlorid Day2_From Start | BKA1: Chlorid Day_Unknown | BKB1: Chlorid Day1 | BKC1: Chlorid Day2 | BKD1: Chlorid Day22 | BKE1: Chlorid Day24 | BKF1: Serum-Eisen Day11_From Start | BKG1: Serum-Eisen Day_Unknown | BKH1: Serum-Eisen Day1 | BKI1: Serum-Eisen Day2 | BKJ1: Serum-Eisen Day3 | BKK1: Serum-Eisen Day10 | BKL1: Serum-Eisen Day13 | BKM1: Serum-Eisen Day15 | BKN1: Serum-Eisen Day16 | BKO1: Serum-Eisen Day35 | BKP1: Serum-Eisen Day79 | BKQ1: Ferritin Day12_From Start | BKR1: Ferritin Day7_From Start | BKS1: Ferritin Day_Unknown | BKT1: Ferritin Day1 | BKU1: Ferritin Day2 | BKV1: Ferritin Day3 | BKW1: Ferritin Day4 | BKX1: Ferritin Day10 | BKY1: Ferritin Day13 | BKZ1: Ferritin Day24 | BLA1: TSH Day6 | BLB1: T3 Day6 | BLC1: T4 Day6 | BLD1: Koagulase Day17 | BLE1: Fever Day6_From Start | BLF1: Fever Day_Unknown | BLG1: Fever Day1 | BLH1: Fever Day2 | BLI1: Fever Day3 | BLJ1: Fever Day7 | BLK1: HbA1C Day_Unknown | BLL1: HbA1C Day1 | BLM1: HbA1C Day3 | BLN1: HbA1C Day7 | BLO1: Glucose Day64_From Start | BLP1: Glucose Day11_From Start | BLQ1: Glucose Day8_From Start | BLR1: Glucose Day6_From Start | BLS1: Glucose Day3_From Start | BLT1: Glucose Day2_From Start | BLU1: Glucose Day1_From Start | BLV1: Glucose Day_Unknown | BLW1: Glucose Day1 | BLX1: Glucose Day2 | BLY1: Glucose Day3 | BLZ1: Glucose Day4 | BMA1: Glucose Day5 | BMB1: Glucose Day6 | BMC1: Glucose Day7 | BMD1: Glucose Day8 | BME1: Glucose Day9 | BMF1: Glucose Day10 | BMG1: Glucose Day11 | BMH1: Glucose Day12 | BMI1: Glucose Day13 | BMJ1: Glucose Day14 | BMK1: Glucose Day15 | BML1: Glucose Day16 | BMM1: Glucose Day17 | BMN1: Glucose Day35 | BMO1: Glucose Day49 | BMP1: Glucose Day66 | BMQ1: Glucose Day79 | BMR1: Protein Day3_From Start | BMS1: Protein Day2_From Start | BMT1: Protein Day1_From Start | BMU1: Protein Day_Unknown | BMV1: Protein Day1 | BMW1: Protein Day2 | BMX1: Protein Day4 | BMY1: Protein Day5 | BMZ1: Protein Day6 | BNA1: Protein Day9 | BNB1: Protein Day14 | BNC1: Protein Day25 | BND1: Ammonika Day_Unknown | BNE1: Ammonika Day1 | BNF1: Ammonika Day2 | BNG1: Ammonika Day3 | BNH1: Ammonika Day4 | BNI1: Ammonika Day7 | BNJ1: Lactat Day8_From Start | BOE1: Leukozyten Day_Unknown | BOF1: Leukozyten Day3 | BOH1: UErythrozyten Day_Unknown
